ERROR Internal Server Error: /api/notes/
Traceback (most recent call last):
  File "/home/shinto/Documents/virtual_envs/rate_api/lib/python3.6/site-packages/django/core/handlers/exception.py", line 34, in inner
    response = get_response(request)
  File "/home/shinto/Documents/virtual_envs/rate_api/lib/python3.6/site-packages/django/core/handlers/base.py", line 115, in _get_response
    response = self.process_exception_by_middleware(e, request)
  File "/home/shinto/Documents/virtual_envs/rate_api/lib/python3.6/site-packages/django/core/handlers/base.py", line 113, in _get_response
    response = wrapped_callback(request, *callback_args, **callback_kwargs)
  File "/home/shinto/Documents/virtual_envs/rate_api/lib/python3.6/site-packages/django/views/decorators/csrf.py", line 54, in wrapped_view
    return view_func(*args, **kwargs)
  File "/home/shinto/Documents/virtual_envs/rate_api/lib/python3.6/site-packages/django/views/generic/base.py", line 71, in view
    return self.dispatch(request, *args, **kwargs)
  File "/home/shinto/Documents/virtual_envs/rate_api/lib/python3.6/site-packages/rest_framework/views.py", line 495, in dispatch
    response = self.handle_exception(exc)
  File "/home/shinto/Documents/virtual_envs/rate_api/lib/python3.6/site-packages/rest_framework/views.py", line 455, in handle_exception
    self.raise_uncaught_exception(exc)
  File "/home/shinto/Documents/virtual_envs/rate_api/lib/python3.6/site-packages/rest_framework/views.py", line 492, in dispatch
    response = handler(request, *args, **kwargs)
  File "/home/shinto/Documents/virtual_envs/rate_api/lib/python3.6/site-packages/rest_framework/decorators.py", line 55, in handler
    return func(*args, **kwargs)
TypeError: notes_list() takes 0 positional arguments but 1 was given
ERROR "GET /api/notes/ HTTP/1.1" 500 95016
ERROR Internal Server Error: /api/notes/
Traceback (most recent call last):
  File "/home/shinto/Documents/virtual_envs/rate_api/lib/python3.6/site-packages/django/core/handlers/exception.py", line 34, in inner
    response = get_response(request)
  File "/home/shinto/Documents/virtual_envs/rate_api/lib/python3.6/site-packages/django/core/handlers/base.py", line 115, in _get_response
    response = self.process_exception_by_middleware(e, request)
  File "/home/shinto/Documents/virtual_envs/rate_api/lib/python3.6/site-packages/django/core/handlers/base.py", line 113, in _get_response
    response = wrapped_callback(request, *callback_args, **callback_kwargs)
  File "/home/shinto/Documents/virtual_envs/rate_api/lib/python3.6/site-packages/django/views/decorators/csrf.py", line 54, in wrapped_view
    return view_func(*args, **kwargs)
  File "/home/shinto/Documents/virtual_envs/rate_api/lib/python3.6/site-packages/django/views/generic/base.py", line 71, in view
    return self.dispatch(request, *args, **kwargs)
  File "/home/shinto/Documents/virtual_envs/rate_api/lib/python3.6/site-packages/rest_framework/views.py", line 495, in dispatch
    response = self.handle_exception(exc)
  File "/home/shinto/Documents/virtual_envs/rate_api/lib/python3.6/site-packages/rest_framework/views.py", line 455, in handle_exception
    self.raise_uncaught_exception(exc)
  File "/home/shinto/Documents/virtual_envs/rate_api/lib/python3.6/site-packages/rest_framework/views.py", line 492, in dispatch
    response = handler(request, *args, **kwargs)
  File "/home/shinto/Documents/virtual_envs/rate_api/lib/python3.6/site-packages/rest_framework/decorators.py", line 55, in handler
    return func(*args, **kwargs)
  File "/home/shinto/Documents/projects/rate_project/rate_api/rate_api/api/views.py", line 223, in notes_list
    return response(serializer.data)
NameError: name 'response' is not defined
ERROR "GET /api/notes/ HTTP/1.1" 500 99256
ERROR Internal Server Error: /api/notes/
Traceback (most recent call last):
  File "/home/shinto/Documents/virtual_envs/rate_api/lib/python3.6/site-packages/rest_framework/fields.py", line 453, in get_attribute
    return get_attribute(instance, self.source_attrs)
  File "/home/shinto/Documents/virtual_envs/rate_api/lib/python3.6/site-packages/rest_framework/fields.py", line 101, in get_attribute
    instance = getattr(instance, attr)
AttributeError: 'QuerySet' object has no attribute 'origin_code'

During handling of the above exception, another exception occurred:

Traceback (most recent call last):
  File "/home/shinto/Documents/virtual_envs/rate_api/lib/python3.6/site-packages/django/core/handlers/exception.py", line 34, in inner
    response = get_response(request)
  File "/home/shinto/Documents/virtual_envs/rate_api/lib/python3.6/site-packages/django/core/handlers/base.py", line 115, in _get_response
    response = self.process_exception_by_middleware(e, request)
  File "/home/shinto/Documents/virtual_envs/rate_api/lib/python3.6/site-packages/django/core/handlers/base.py", line 113, in _get_response
    response = wrapped_callback(request, *callback_args, **callback_kwargs)
  File "/home/shinto/Documents/virtual_envs/rate_api/lib/python3.6/site-packages/django/views/decorators/csrf.py", line 54, in wrapped_view
    return view_func(*args, **kwargs)
  File "/home/shinto/Documents/virtual_envs/rate_api/lib/python3.6/site-packages/django/views/generic/base.py", line 71, in view
    return self.dispatch(request, *args, **kwargs)
  File "/home/shinto/Documents/virtual_envs/rate_api/lib/python3.6/site-packages/rest_framework/views.py", line 495, in dispatch
    response = self.handle_exception(exc)
  File "/home/shinto/Documents/virtual_envs/rate_api/lib/python3.6/site-packages/rest_framework/views.py", line 455, in handle_exception
    self.raise_uncaught_exception(exc)
  File "/home/shinto/Documents/virtual_envs/rate_api/lib/python3.6/site-packages/rest_framework/views.py", line 492, in dispatch
    response = handler(request, *args, **kwargs)
  File "/home/shinto/Documents/virtual_envs/rate_api/lib/python3.6/site-packages/rest_framework/decorators.py", line 55, in handler
    return func(*args, **kwargs)
  File "/home/shinto/Documents/projects/rate_project/rate_api/rate_api/api/views.py", line 223, in notes_list
    return Response(serializer.data)
  File "/home/shinto/Documents/virtual_envs/rate_api/lib/python3.6/site-packages/rest_framework/serializers.py", line 563, in data
    ret = super(Serializer, self).data
  File "/home/shinto/Documents/virtual_envs/rate_api/lib/python3.6/site-packages/rest_framework/serializers.py", line 262, in data
    self._data = self.to_representation(self.instance)
  File "/home/shinto/Documents/virtual_envs/rate_api/lib/python3.6/site-packages/rest_framework/serializers.py", line 517, in to_representation
    attribute = field.get_attribute(instance)
  File "/home/shinto/Documents/virtual_envs/rate_api/lib/python3.6/site-packages/rest_framework/fields.py", line 474, in get_attribute
    raise type(exc)(msg)
AttributeError: Got AttributeError when attempting to get a value for field `origin_code` on serializer `PricesSerializer`.
The serializer field might be named incorrectly and not match any attribute or key on the `QuerySet` instance.
Original exception text was: 'QuerySet' object has no attribute 'origin_code'.
ERROR "GET /api/notes/ HTTP/1.1" 500 127519
ERROR Internal Server Error: /api/upload/
Traceback (most recent call last):
  File "/home/shinto/Documents/virtual_envs/rate_api/lib/python3.6/site-packages/django/core/handlers/exception.py", line 34, in inner
    response = get_response(request)
  File "/home/shinto/Documents/virtual_envs/rate_api/lib/python3.6/site-packages/django/core/handlers/base.py", line 115, in _get_response
    response = self.process_exception_by_middleware(e, request)
  File "/home/shinto/Documents/virtual_envs/rate_api/lib/python3.6/site-packages/django/core/handlers/base.py", line 113, in _get_response
    response = wrapped_callback(request, *callback_args, **callback_kwargs)
  File "/home/shinto/Documents/virtual_envs/rate_api/lib/python3.6/site-packages/django/views/decorators/csrf.py", line 54, in wrapped_view
    return view_func(*args, **kwargs)
  File "/home/shinto/Documents/virtual_envs/rate_api/lib/python3.6/site-packages/django/views/generic/base.py", line 71, in view
    return self.dispatch(request, *args, **kwargs)
  File "/home/shinto/Documents/virtual_envs/rate_api/lib/python3.6/site-packages/rest_framework/views.py", line 495, in dispatch
    response = self.handle_exception(exc)
  File "/home/shinto/Documents/virtual_envs/rate_api/lib/python3.6/site-packages/rest_framework/views.py", line 455, in handle_exception
    self.raise_uncaught_exception(exc)
  File "/home/shinto/Documents/virtual_envs/rate_api/lib/python3.6/site-packages/rest_framework/views.py", line 492, in dispatch
    response = handler(request, *args, **kwargs)
  File "/home/shinto/Documents/projects/rate_project/rate_api/rate_api/api/views.py", line 249, in post
    serializer = PricesSerializer(data=data)
TypeError: __init__() got an unexpected keyword argument 'data'
ERROR "POST /api/upload/ HTTP/1.1" 500 95450
ERROR Internal Server Error: /api/upload/
Traceback (most recent call last):
  File "/home/shinto/Documents/virtual_envs/rate_api/lib/python3.6/site-packages/django/core/handlers/exception.py", line 34, in inner
    response = get_response(request)
  File "/home/shinto/Documents/virtual_envs/rate_api/lib/python3.6/site-packages/django/core/handlers/base.py", line 115, in _get_response
    response = self.process_exception_by_middleware(e, request)
  File "/home/shinto/Documents/virtual_envs/rate_api/lib/python3.6/site-packages/django/core/handlers/base.py", line 113, in _get_response
    response = wrapped_callback(request, *callback_args, **callback_kwargs)
  File "/home/shinto/Documents/virtual_envs/rate_api/lib/python3.6/site-packages/django/views/decorators/csrf.py", line 54, in wrapped_view
    return view_func(*args, **kwargs)
  File "/home/shinto/Documents/virtual_envs/rate_api/lib/python3.6/site-packages/django/views/generic/base.py", line 71, in view
    return self.dispatch(request, *args, **kwargs)
  File "/home/shinto/Documents/virtual_envs/rate_api/lib/python3.6/site-packages/rest_framework/views.py", line 495, in dispatch
    response = self.handle_exception(exc)
  File "/home/shinto/Documents/virtual_envs/rate_api/lib/python3.6/site-packages/rest_framework/views.py", line 455, in handle_exception
    self.raise_uncaught_exception(exc)
  File "/home/shinto/Documents/virtual_envs/rate_api/lib/python3.6/site-packages/rest_framework/views.py", line 492, in dispatch
    response = handler(request, *args, **kwargs)
  File "/home/shinto/Documents/projects/rate_project/rate_api/rate_api/api/views.py", line 249, in post
    serializer = PricesSerializer(data=data)
TypeError: __init__() got an unexpected keyword argument 'data'
ERROR "POST /api/upload/ HTTP/1.1" 500 17516
ERROR Internal Server Error: /api/upload/
Traceback (most recent call last):
  File "/home/shinto/Documents/virtual_envs/rate_api/lib/python3.6/site-packages/django/core/handlers/exception.py", line 34, in inner
    response = get_response(request)
  File "/home/shinto/Documents/virtual_envs/rate_api/lib/python3.6/site-packages/django/core/handlers/base.py", line 115, in _get_response
    response = self.process_exception_by_middleware(e, request)
  File "/home/shinto/Documents/virtual_envs/rate_api/lib/python3.6/site-packages/django/core/handlers/base.py", line 113, in _get_response
    response = wrapped_callback(request, *callback_args, **callback_kwargs)
  File "/home/shinto/Documents/virtual_envs/rate_api/lib/python3.6/site-packages/django/views/decorators/csrf.py", line 54, in wrapped_view
    return view_func(*args, **kwargs)
  File "/home/shinto/Documents/virtual_envs/rate_api/lib/python3.6/site-packages/django/views/generic/base.py", line 71, in view
    return self.dispatch(request, *args, **kwargs)
  File "/home/shinto/Documents/virtual_envs/rate_api/lib/python3.6/site-packages/rest_framework/views.py", line 495, in dispatch
    response = self.handle_exception(exc)
  File "/home/shinto/Documents/virtual_envs/rate_api/lib/python3.6/site-packages/rest_framework/views.py", line 455, in handle_exception
    self.raise_uncaught_exception(exc)
  File "/home/shinto/Documents/virtual_envs/rate_api/lib/python3.6/site-packages/rest_framework/views.py", line 492, in dispatch
    response = handler(request, *args, **kwargs)
  File "/home/shinto/Documents/projects/rate_project/rate_api/rate_api/api/views.py", line 249, in post
    serializer = PricesSerializer(data=data)
TypeError: __init__() got an unexpected keyword argument 'data'
ERROR "POST /api/upload/ HTTP/1.1" 500 17516
ERROR Internal Server Error: /api/upload/
Traceback (most recent call last):
  File "/home/shinto/Documents/virtual_envs/rate_api/lib/python3.6/site-packages/django/core/handlers/exception.py", line 34, in inner
    response = get_response(request)
  File "/home/shinto/Documents/virtual_envs/rate_api/lib/python3.6/site-packages/django/core/handlers/base.py", line 115, in _get_response
    response = self.process_exception_by_middleware(e, request)
  File "/home/shinto/Documents/virtual_envs/rate_api/lib/python3.6/site-packages/django/core/handlers/base.py", line 113, in _get_response
    response = wrapped_callback(request, *callback_args, **callback_kwargs)
  File "/home/shinto/Documents/virtual_envs/rate_api/lib/python3.6/site-packages/django/views/decorators/csrf.py", line 54, in wrapped_view
    return view_func(*args, **kwargs)
  File "/home/shinto/Documents/virtual_envs/rate_api/lib/python3.6/site-packages/django/views/generic/base.py", line 71, in view
    return self.dispatch(request, *args, **kwargs)
  File "/home/shinto/Documents/virtual_envs/rate_api/lib/python3.6/site-packages/rest_framework/views.py", line 495, in dispatch
    response = self.handle_exception(exc)
  File "/home/shinto/Documents/virtual_envs/rate_api/lib/python3.6/site-packages/rest_framework/views.py", line 455, in handle_exception
    self.raise_uncaught_exception(exc)
  File "/home/shinto/Documents/virtual_envs/rate_api/lib/python3.6/site-packages/rest_framework/views.py", line 492, in dispatch
    response = handler(request, *args, **kwargs)
  File "/home/shinto/Documents/projects/rate_project/rate_api/rate_api/api/views.py", line 249, in post
    serializer = PricesSerializer(data=data)
  File "/home/shinto/Documents/projects/rate_project/rate_api/rate_api/api/serializers.py", line 29, in __init__
    serializer.is_valid(raise_exception=True)
NameError: name 'serializer' is not defined
ERROR "POST /api/upload/ HTTP/1.1" 500 17634
ERROR Internal Server Error: /api/upload/
Traceback (most recent call last):
  File "/home/shinto/Documents/virtual_envs/rate_api/lib/python3.6/site-packages/django/core/handlers/exception.py", line 34, in inner
    response = get_response(request)
  File "/home/shinto/Documents/virtual_envs/rate_api/lib/python3.6/site-packages/django/core/handlers/base.py", line 115, in _get_response
    response = self.process_exception_by_middleware(e, request)
  File "/home/shinto/Documents/virtual_envs/rate_api/lib/python3.6/site-packages/django/core/handlers/base.py", line 113, in _get_response
    response = wrapped_callback(request, *callback_args, **callback_kwargs)
  File "/home/shinto/Documents/virtual_envs/rate_api/lib/python3.6/site-packages/django/views/decorators/csrf.py", line 54, in wrapped_view
    return view_func(*args, **kwargs)
  File "/home/shinto/Documents/virtual_envs/rate_api/lib/python3.6/site-packages/django/views/generic/base.py", line 71, in view
    return self.dispatch(request, *args, **kwargs)
  File "/home/shinto/Documents/virtual_envs/rate_api/lib/python3.6/site-packages/rest_framework/views.py", line 495, in dispatch
    response = self.handle_exception(exc)
  File "/home/shinto/Documents/virtual_envs/rate_api/lib/python3.6/site-packages/rest_framework/views.py", line 455, in handle_exception
    self.raise_uncaught_exception(exc)
  File "/home/shinto/Documents/virtual_envs/rate_api/lib/python3.6/site-packages/rest_framework/views.py", line 492, in dispatch
    response = handler(request, *args, **kwargs)
  File "/home/shinto/Documents/projects/rate_project/rate_api/rate_api/api/views.py", line 249, in post
    serializer = PricesSerializer(data=data)
  File "/home/shinto/Documents/projects/rate_project/rate_api/rate_api/api/serializers.py", line 29, in __init__
    serializer = PricesSerializer(data=data)
  File "/home/shinto/Documents/projects/rate_project/rate_api/rate_api/api/serializers.py", line 29, in __init__
    serializer = PricesSerializer(data=data)
  File "/home/shinto/Documents/projects/rate_project/rate_api/rate_api/api/serializers.py", line 29, in __init__
    serializer = PricesSerializer(data=data)
  [Previous line repeated 228 more times]
  File "/home/shinto/Documents/virtual_envs/rate_api/lib/python3.6/site-packages/rest_framework/serializers.py", line 125, in __new__
    return super(BaseSerializer, cls).__new__(cls, *args, **kwargs)
RecursionError: maximum recursion depth exceeded in comparison
ERROR "POST /api/upload/ HTTP/1.1" 500 53982
ERROR Internal Server Error: /api/upload/
Traceback (most recent call last):
  File "/home/shinto/Documents/virtual_envs/rate_api/lib/python3.6/site-packages/django/core/handlers/exception.py", line 34, in inner
    response = get_response(request)
  File "/home/shinto/Documents/virtual_envs/rate_api/lib/python3.6/site-packages/django/core/handlers/base.py", line 115, in _get_response
    response = self.process_exception_by_middleware(e, request)
  File "/home/shinto/Documents/virtual_envs/rate_api/lib/python3.6/site-packages/django/core/handlers/base.py", line 113, in _get_response
    response = wrapped_callback(request, *callback_args, **callback_kwargs)
  File "/home/shinto/Documents/virtual_envs/rate_api/lib/python3.6/site-packages/django/views/decorators/csrf.py", line 54, in wrapped_view
    return view_func(*args, **kwargs)
  File "/home/shinto/Documents/virtual_envs/rate_api/lib/python3.6/site-packages/django/views/generic/base.py", line 71, in view
    return self.dispatch(request, *args, **kwargs)
  File "/home/shinto/Documents/virtual_envs/rate_api/lib/python3.6/site-packages/rest_framework/views.py", line 495, in dispatch
    response = self.handle_exception(exc)
  File "/home/shinto/Documents/virtual_envs/rate_api/lib/python3.6/site-packages/rest_framework/views.py", line 455, in handle_exception
    self.raise_uncaught_exception(exc)
  File "/home/shinto/Documents/virtual_envs/rate_api/lib/python3.6/site-packages/rest_framework/views.py", line 492, in dispatch
    response = handler(request, *args, **kwargs)
  File "/home/shinto/Documents/projects/rate_project/rate_api/rate_api/api/views.py", line 249, in post
    serializer = PricesSerializer(data=data)
  File "/home/shinto/Documents/projects/rate_project/rate_api/rate_api/api/serializers.py", line 29, in __init__
    serializer = PricesSerializer(data=data)
  File "/home/shinto/Documents/projects/rate_project/rate_api/rate_api/api/serializers.py", line 29, in __init__
    serializer = PricesSerializer(data=data)
  File "/home/shinto/Documents/projects/rate_project/rate_api/rate_api/api/serializers.py", line 29, in __init__
    serializer = PricesSerializer(data=data)
  [Previous line repeated 228 more times]
  File "/home/shinto/Documents/virtual_envs/rate_api/lib/python3.6/site-packages/rest_framework/serializers.py", line 125, in __new__
    return super(BaseSerializer, cls).__new__(cls, *args, **kwargs)
RecursionError: maximum recursion depth exceeded in comparison
ERROR "POST /api/upload/ HTTP/1.1" 500 53982
ERROR Internal Server Error: /api/upload/
Traceback (most recent call last):
  File "/home/shinto/Documents/virtual_envs/rate_api/lib/python3.6/site-packages/django/core/handlers/exception.py", line 34, in inner
    response = get_response(request)
  File "/home/shinto/Documents/virtual_envs/rate_api/lib/python3.6/site-packages/django/core/handlers/base.py", line 115, in _get_response
    response = self.process_exception_by_middleware(e, request)
  File "/home/shinto/Documents/virtual_envs/rate_api/lib/python3.6/site-packages/django/core/handlers/base.py", line 113, in _get_response
    response = wrapped_callback(request, *callback_args, **callback_kwargs)
  File "/home/shinto/Documents/virtual_envs/rate_api/lib/python3.6/site-packages/django/views/decorators/csrf.py", line 54, in wrapped_view
    return view_func(*args, **kwargs)
  File "/home/shinto/Documents/virtual_envs/rate_api/lib/python3.6/site-packages/django/views/generic/base.py", line 71, in view
    return self.dispatch(request, *args, **kwargs)
  File "/home/shinto/Documents/virtual_envs/rate_api/lib/python3.6/site-packages/rest_framework/views.py", line 495, in dispatch
    response = self.handle_exception(exc)
  File "/home/shinto/Documents/virtual_envs/rate_api/lib/python3.6/site-packages/rest_framework/views.py", line 455, in handle_exception
    self.raise_uncaught_exception(exc)
  File "/home/shinto/Documents/virtual_envs/rate_api/lib/python3.6/site-packages/rest_framework/views.py", line 492, in dispatch
    response = handler(request, *args, **kwargs)
  File "/home/shinto/Documents/projects/rate_project/rate_api/rate_api/api/views.py", line 249, in post
    serializer = PricesSerializer(data=data)
  File "/home/shinto/Documents/projects/rate_project/rate_api/rate_api/api/serializers.py", line 29, in __init__
    serializer = PricesSerializer(data=data)
  File "/home/shinto/Documents/projects/rate_project/rate_api/rate_api/api/serializers.py", line 29, in __init__
    serializer = PricesSerializer(data=data)
  File "/home/shinto/Documents/projects/rate_project/rate_api/rate_api/api/serializers.py", line 29, in __init__
    serializer = PricesSerializer(data=data)
  [Previous line repeated 228 more times]
  File "/home/shinto/Documents/virtual_envs/rate_api/lib/python3.6/site-packages/rest_framework/serializers.py", line 125, in __new__
    return super(BaseSerializer, cls).__new__(cls, *args, **kwargs)
RecursionError: maximum recursion depth exceeded in comparison
ERROR "POST /api/upload/ HTTP/1.1" 500 53982
ERROR Internal Server Error: /api/upload/
Traceback (most recent call last):
  File "/home/shinto/Documents/virtual_envs/rate_api/lib/python3.6/site-packages/django/core/handlers/exception.py", line 34, in inner
    response = get_response(request)
  File "/home/shinto/Documents/virtual_envs/rate_api/lib/python3.6/site-packages/django/core/handlers/base.py", line 115, in _get_response
    response = self.process_exception_by_middleware(e, request)
  File "/home/shinto/Documents/virtual_envs/rate_api/lib/python3.6/site-packages/django/core/handlers/base.py", line 113, in _get_response
    response = wrapped_callback(request, *callback_args, **callback_kwargs)
  File "/home/shinto/Documents/virtual_envs/rate_api/lib/python3.6/site-packages/django/views/decorators/csrf.py", line 54, in wrapped_view
    return view_func(*args, **kwargs)
  File "/home/shinto/Documents/virtual_envs/rate_api/lib/python3.6/site-packages/django/views/generic/base.py", line 71, in view
    return self.dispatch(request, *args, **kwargs)
  File "/home/shinto/Documents/virtual_envs/rate_api/lib/python3.6/site-packages/rest_framework/views.py", line 495, in dispatch
    response = self.handle_exception(exc)
  File "/home/shinto/Documents/virtual_envs/rate_api/lib/python3.6/site-packages/rest_framework/views.py", line 455, in handle_exception
    self.raise_uncaught_exception(exc)
  File "/home/shinto/Documents/virtual_envs/rate_api/lib/python3.6/site-packages/rest_framework/views.py", line 492, in dispatch
    response = handler(request, *args, **kwargs)
  File "/home/shinto/Documents/projects/rate_project/rate_api/rate_api/api/views.py", line 242, in post
    serializer.is_valid(raise_exception=True)
  File "/home/shinto/Documents/virtual_envs/rate_api/lib/python3.6/site-packages/rest_framework/serializers.py", line 236, in is_valid
    self._validated_data = self.run_validation(self.initial_data)
  File "/home/shinto/Documents/virtual_envs/rate_api/lib/python3.6/site-packages/rest_framework/serializers.py", line 438, in run_validation
    assert value is not None, '.validate() should return the validated data'
AssertionError: .validate() should return the validated data
ERROR "POST /api/upload/ HTTP/1.1" 500 105149
ERROR Internal Server Error: /api/upload/
Traceback (most recent call last):
  File "/home/shinto/Documents/virtual_envs/rate_api/lib/python3.6/site-packages/django/core/handlers/exception.py", line 34, in inner
    response = get_response(request)
  File "/home/shinto/Documents/virtual_envs/rate_api/lib/python3.6/site-packages/django/core/handlers/base.py", line 115, in _get_response
    response = self.process_exception_by_middleware(e, request)
  File "/home/shinto/Documents/virtual_envs/rate_api/lib/python3.6/site-packages/django/core/handlers/base.py", line 113, in _get_response
    response = wrapped_callback(request, *callback_args, **callback_kwargs)
  File "/home/shinto/Documents/virtual_envs/rate_api/lib/python3.6/site-packages/django/views/decorators/csrf.py", line 54, in wrapped_view
    return view_func(*args, **kwargs)
  File "/home/shinto/Documents/virtual_envs/rate_api/lib/python3.6/site-packages/django/views/generic/base.py", line 71, in view
    return self.dispatch(request, *args, **kwargs)
  File "/home/shinto/Documents/virtual_envs/rate_api/lib/python3.6/site-packages/rest_framework/views.py", line 497, in dispatch
    self.response = self.finalize_response(request, response, *args, **kwargs)
  File "/home/shinto/Documents/virtual_envs/rate_api/lib/python3.6/site-packages/rest_framework/views.py", line 412, in finalize_response
    % type(response)
AssertionError: Expected a `Response`, `HttpResponse` or `HttpStreamingResponse` to be returned from the view, but received a `<class 'bool'>`
ERROR "POST /api/upload/ HTTP/1.1" 500 18967
ERROR Internal Server Error: /api/upload/
Traceback (most recent call last):
  File "/home/shinto/Documents/virtual_envs/rate_api/lib/python3.6/site-packages/django/core/handlers/exception.py", line 34, in inner
    response = get_response(request)
  File "/home/shinto/Documents/virtual_envs/rate_api/lib/python3.6/site-packages/django/core/handlers/base.py", line 115, in _get_response
    response = self.process_exception_by_middleware(e, request)
  File "/home/shinto/Documents/virtual_envs/rate_api/lib/python3.6/site-packages/django/core/handlers/base.py", line 113, in _get_response
    response = wrapped_callback(request, *callback_args, **callback_kwargs)
  File "/home/shinto/Documents/virtual_envs/rate_api/lib/python3.6/site-packages/django/views/decorators/csrf.py", line 54, in wrapped_view
    return view_func(*args, **kwargs)
  File "/home/shinto/Documents/virtual_envs/rate_api/lib/python3.6/site-packages/django/views/generic/base.py", line 71, in view
    return self.dispatch(request, *args, **kwargs)
  File "/home/shinto/Documents/virtual_envs/rate_api/lib/python3.6/site-packages/rest_framework/views.py", line 497, in dispatch
    self.response = self.finalize_response(request, response, *args, **kwargs)
  File "/home/shinto/Documents/virtual_envs/rate_api/lib/python3.6/site-packages/rest_framework/views.py", line 412, in finalize_response
    % type(response)
AssertionError: Expected a `Response`, `HttpResponse` or `HttpStreamingResponse` to be returned from the view, but received a `<class 'bool'>`
ERROR "POST /api/upload/ HTTP/1.1" 500 18967
ERROR Internal Server Error: /api/upload/
Traceback (most recent call last):
  File "/home/shinto/Documents/virtual_envs/rate_api/lib/python3.6/site-packages/django/core/handlers/exception.py", line 34, in inner
    response = get_response(request)
  File "/home/shinto/Documents/virtual_envs/rate_api/lib/python3.6/site-packages/django/core/handlers/base.py", line 115, in _get_response
    response = self.process_exception_by_middleware(e, request)
  File "/home/shinto/Documents/virtual_envs/rate_api/lib/python3.6/site-packages/django/core/handlers/base.py", line 113, in _get_response
    response = wrapped_callback(request, *callback_args, **callback_kwargs)
  File "/home/shinto/Documents/virtual_envs/rate_api/lib/python3.6/site-packages/django/views/decorators/csrf.py", line 54, in wrapped_view
    return view_func(*args, **kwargs)
  File "/home/shinto/Documents/virtual_envs/rate_api/lib/python3.6/site-packages/django/views/generic/base.py", line 71, in view
    return self.dispatch(request, *args, **kwargs)
  File "/home/shinto/Documents/virtual_envs/rate_api/lib/python3.6/site-packages/rest_framework/views.py", line 497, in dispatch
    self.response = self.finalize_response(request, response, *args, **kwargs)
  File "/home/shinto/Documents/virtual_envs/rate_api/lib/python3.6/site-packages/rest_framework/views.py", line 412, in finalize_response
    % type(response)
AssertionError: Expected a `Response`, `HttpResponse` or `HttpStreamingResponse` to be returned from the view, but received a `<class 'bool'>`
ERROR "POST /api/upload/ HTTP/1.1" 500 18967
ERROR Internal Server Error: /api/upload/
Traceback (most recent call last):
  File "/home/shinto/Documents/virtual_envs/rate_api/lib/python3.6/site-packages/django/core/handlers/exception.py", line 34, in inner
    response = get_response(request)
  File "/home/shinto/Documents/virtual_envs/rate_api/lib/python3.6/site-packages/django/core/handlers/base.py", line 115, in _get_response
    response = self.process_exception_by_middleware(e, request)
  File "/home/shinto/Documents/virtual_envs/rate_api/lib/python3.6/site-packages/django/core/handlers/base.py", line 113, in _get_response
    response = wrapped_callback(request, *callback_args, **callback_kwargs)
  File "/home/shinto/Documents/virtual_envs/rate_api/lib/python3.6/site-packages/django/views/decorators/csrf.py", line 54, in wrapped_view
    return view_func(*args, **kwargs)
  File "/home/shinto/Documents/virtual_envs/rate_api/lib/python3.6/site-packages/django/views/generic/base.py", line 71, in view
    return self.dispatch(request, *args, **kwargs)
  File "/home/shinto/Documents/virtual_envs/rate_api/lib/python3.6/site-packages/rest_framework/views.py", line 497, in dispatch
    self.response = self.finalize_response(request, response, *args, **kwargs)
  File "/home/shinto/Documents/virtual_envs/rate_api/lib/python3.6/site-packages/rest_framework/views.py", line 412, in finalize_response
    % type(response)
AssertionError: Expected a `Response`, `HttpResponse` or `HttpStreamingResponse` to be returned from the view, but received a `<class 'bool'>`
ERROR "POST /api/upload/ HTTP/1.1" 500 18967
ERROR Internal Server Error: /api/upload/
Traceback (most recent call last):
  File "/home/shinto/Documents/virtual_envs/rate_api/lib/python3.6/site-packages/django/core/handlers/exception.py", line 34, in inner
    response = get_response(request)
  File "/home/shinto/Documents/virtual_envs/rate_api/lib/python3.6/site-packages/django/core/handlers/base.py", line 115, in _get_response
    response = self.process_exception_by_middleware(e, request)
  File "/home/shinto/Documents/virtual_envs/rate_api/lib/python3.6/site-packages/django/core/handlers/base.py", line 113, in _get_response
    response = wrapped_callback(request, *callback_args, **callback_kwargs)
  File "/home/shinto/Documents/virtual_envs/rate_api/lib/python3.6/site-packages/django/views/decorators/csrf.py", line 54, in wrapped_view
    return view_func(*args, **kwargs)
  File "/home/shinto/Documents/virtual_envs/rate_api/lib/python3.6/site-packages/django/views/generic/base.py", line 71, in view
    return self.dispatch(request, *args, **kwargs)
  File "/home/shinto/Documents/virtual_envs/rate_api/lib/python3.6/site-packages/rest_framework/views.py", line 497, in dispatch
    self.response = self.finalize_response(request, response, *args, **kwargs)
  File "/home/shinto/Documents/virtual_envs/rate_api/lib/python3.6/site-packages/rest_framework/views.py", line 412, in finalize_response
    % type(response)
AssertionError: Expected a `Response`, `HttpResponse` or `HttpStreamingResponse` to be returned from the view, but received a `<class 'bool'>`
ERROR "POST /api/upload/ HTTP/1.1" 500 18967
ERROR Internal Server Error: /api/upload/
Traceback (most recent call last):
  File "/home/shinto/Documents/virtual_envs/rate_api/lib/python3.6/site-packages/django/db/backends/utils.py", line 84, in _execute
    return self.cursor.execute(sql, params)
psycopg2.errors.UndefinedColumn: column api_prices.id does not exist
LINE 1: ...GGZ', 'EETLL', '2016-01-01'::date, 217) RETURNING "api_price...
                                                             ^


The above exception was the direct cause of the following exception:

Traceback (most recent call last):
  File "/home/shinto/Documents/virtual_envs/rate_api/lib/python3.6/site-packages/django/core/handlers/exception.py", line 34, in inner
    response = get_response(request)
  File "/home/shinto/Documents/virtual_envs/rate_api/lib/python3.6/site-packages/django/core/handlers/base.py", line 115, in _get_response
    response = self.process_exception_by_middleware(e, request)
  File "/home/shinto/Documents/virtual_envs/rate_api/lib/python3.6/site-packages/django/core/handlers/base.py", line 113, in _get_response
    response = wrapped_callback(request, *callback_args, **callback_kwargs)
  File "/home/shinto/Documents/virtual_envs/rate_api/lib/python3.6/site-packages/django/views/decorators/csrf.py", line 54, in wrapped_view
    return view_func(*args, **kwargs)
  File "/home/shinto/Documents/virtual_envs/rate_api/lib/python3.6/site-packages/django/views/generic/base.py", line 71, in view
    return self.dispatch(request, *args, **kwargs)
  File "/home/shinto/Documents/virtual_envs/rate_api/lib/python3.6/site-packages/rest_framework/views.py", line 495, in dispatch
    response = self.handle_exception(exc)
  File "/home/shinto/Documents/virtual_envs/rate_api/lib/python3.6/site-packages/rest_framework/views.py", line 455, in handle_exception
    self.raise_uncaught_exception(exc)
  File "/home/shinto/Documents/virtual_envs/rate_api/lib/python3.6/site-packages/rest_framework/views.py", line 492, in dispatch
    response = handler(request, *args, **kwargs)
  File "/home/shinto/Documents/projects/rate_project/rate_api/rate_api/api/views.py", line 264, in post
    p.save()
  File "/home/shinto/Documents/virtual_envs/rate_api/lib/python3.6/site-packages/django/db/models/base.py", line 741, in save
    force_update=force_update, update_fields=update_fields)
  File "/home/shinto/Documents/virtual_envs/rate_api/lib/python3.6/site-packages/django/db/models/base.py", line 779, in save_base
    force_update, using, update_fields,
  File "/home/shinto/Documents/virtual_envs/rate_api/lib/python3.6/site-packages/django/db/models/base.py", line 870, in _save_table
    result = self._do_insert(cls._base_manager, using, fields, update_pk, raw)
  File "/home/shinto/Documents/virtual_envs/rate_api/lib/python3.6/site-packages/django/db/models/base.py", line 908, in _do_insert
    using=using, raw=raw)
  File "/home/shinto/Documents/virtual_envs/rate_api/lib/python3.6/site-packages/django/db/models/manager.py", line 82, in manager_method
    return getattr(self.get_queryset(), name)(*args, **kwargs)
  File "/home/shinto/Documents/virtual_envs/rate_api/lib/python3.6/site-packages/django/db/models/query.py", line 1186, in _insert
    return query.get_compiler(using=using).execute_sql(return_id)
  File "/home/shinto/Documents/virtual_envs/rate_api/lib/python3.6/site-packages/django/db/models/sql/compiler.py", line 1335, in execute_sql
    cursor.execute(sql, params)
  File "/home/shinto/Documents/virtual_envs/rate_api/lib/python3.6/site-packages/django/db/backends/utils.py", line 99, in execute
    return super().execute(sql, params)
  File "/home/shinto/Documents/virtual_envs/rate_api/lib/python3.6/site-packages/django/db/backends/utils.py", line 67, in execute
    return self._execute_with_wrappers(sql, params, many=False, executor=self._execute)
  File "/home/shinto/Documents/virtual_envs/rate_api/lib/python3.6/site-packages/django/db/backends/utils.py", line 76, in _execute_with_wrappers
    return executor(sql, params, many, context)
  File "/home/shinto/Documents/virtual_envs/rate_api/lib/python3.6/site-packages/django/db/backends/utils.py", line 84, in _execute
    return self.cursor.execute(sql, params)
  File "/home/shinto/Documents/virtual_envs/rate_api/lib/python3.6/site-packages/django/db/utils.py", line 89, in __exit__
    raise dj_exc_value.with_traceback(traceback) from exc_value
  File "/home/shinto/Documents/virtual_envs/rate_api/lib/python3.6/site-packages/django/db/backends/utils.py", line 84, in _execute
    return self.cursor.execute(sql, params)
django.db.utils.ProgrammingError: column api_prices.id does not exist
LINE 1: ...GGZ', 'EETLL', '2016-01-01'::date, 217) RETURNING "api_price...
                                                             ^

ERROR "POST /api/upload/ HTTP/1.1" 500 170855
ERROR Internal Server Error: /api/upload/
Traceback (most recent call last):
  File "/home/shinto/Documents/virtual_envs/rate_api/lib/python3.6/site-packages/django/db/backends/utils.py", line 84, in _execute
    return self.cursor.execute(sql, params)
psycopg2.errors.UndefinedColumn: column api_prices.id does not exist
LINE 1: ...GGZ', 'EETLL', '2016-01-01'::date, 217) RETURNING "api_price...
                                                             ^


The above exception was the direct cause of the following exception:

Traceback (most recent call last):
  File "/home/shinto/Documents/virtual_envs/rate_api/lib/python3.6/site-packages/django/core/handlers/exception.py", line 34, in inner
    response = get_response(request)
  File "/home/shinto/Documents/virtual_envs/rate_api/lib/python3.6/site-packages/django/core/handlers/base.py", line 115, in _get_response
    response = self.process_exception_by_middleware(e, request)
  File "/home/shinto/Documents/virtual_envs/rate_api/lib/python3.6/site-packages/django/core/handlers/base.py", line 113, in _get_response
    response = wrapped_callback(request, *callback_args, **callback_kwargs)
  File "/home/shinto/Documents/virtual_envs/rate_api/lib/python3.6/site-packages/django/views/decorators/csrf.py", line 54, in wrapped_view
    return view_func(*args, **kwargs)
  File "/home/shinto/Documents/virtual_envs/rate_api/lib/python3.6/site-packages/django/views/generic/base.py", line 71, in view
    return self.dispatch(request, *args, **kwargs)
  File "/home/shinto/Documents/virtual_envs/rate_api/lib/python3.6/site-packages/rest_framework/views.py", line 495, in dispatch
    response = self.handle_exception(exc)
  File "/home/shinto/Documents/virtual_envs/rate_api/lib/python3.6/site-packages/rest_framework/views.py", line 455, in handle_exception
    self.raise_uncaught_exception(exc)
  File "/home/shinto/Documents/virtual_envs/rate_api/lib/python3.6/site-packages/rest_framework/views.py", line 492, in dispatch
    response = handler(request, *args, **kwargs)
  File "/home/shinto/Documents/projects/rate_project/rate_api/rate_api/api/views.py", line 264, in post
    p.save()
  File "/home/shinto/Documents/virtual_envs/rate_api/lib/python3.6/site-packages/django/db/models/base.py", line 741, in save
    force_update=force_update, update_fields=update_fields)
  File "/home/shinto/Documents/virtual_envs/rate_api/lib/python3.6/site-packages/django/db/models/base.py", line 779, in save_base
    force_update, using, update_fields,
  File "/home/shinto/Documents/virtual_envs/rate_api/lib/python3.6/site-packages/django/db/models/base.py", line 870, in _save_table
    result = self._do_insert(cls._base_manager, using, fields, update_pk, raw)
  File "/home/shinto/Documents/virtual_envs/rate_api/lib/python3.6/site-packages/django/db/models/base.py", line 908, in _do_insert
    using=using, raw=raw)
  File "/home/shinto/Documents/virtual_envs/rate_api/lib/python3.6/site-packages/django/db/models/manager.py", line 82, in manager_method
    return getattr(self.get_queryset(), name)(*args, **kwargs)
  File "/home/shinto/Documents/virtual_envs/rate_api/lib/python3.6/site-packages/django/db/models/query.py", line 1186, in _insert
    return query.get_compiler(using=using).execute_sql(return_id)
  File "/home/shinto/Documents/virtual_envs/rate_api/lib/python3.6/site-packages/django/db/models/sql/compiler.py", line 1335, in execute_sql
    cursor.execute(sql, params)
  File "/home/shinto/Documents/virtual_envs/rate_api/lib/python3.6/site-packages/django/db/backends/utils.py", line 99, in execute
    return super().execute(sql, params)
  File "/home/shinto/Documents/virtual_envs/rate_api/lib/python3.6/site-packages/django/db/backends/utils.py", line 67, in execute
    return self._execute_with_wrappers(sql, params, many=False, executor=self._execute)
  File "/home/shinto/Documents/virtual_envs/rate_api/lib/python3.6/site-packages/django/db/backends/utils.py", line 76, in _execute_with_wrappers
    return executor(sql, params, many, context)
  File "/home/shinto/Documents/virtual_envs/rate_api/lib/python3.6/site-packages/django/db/backends/utils.py", line 84, in _execute
    return self.cursor.execute(sql, params)
  File "/home/shinto/Documents/virtual_envs/rate_api/lib/python3.6/site-packages/django/db/utils.py", line 89, in __exit__
    raise dj_exc_value.with_traceback(traceback) from exc_value
  File "/home/shinto/Documents/virtual_envs/rate_api/lib/python3.6/site-packages/django/db/backends/utils.py", line 84, in _execute
    return self.cursor.execute(sql, params)
django.db.utils.ProgrammingError: column api_prices.id does not exist
LINE 1: ...GGZ', 'EETLL', '2016-01-01'::date, 217) RETURNING "api_price...
                                                             ^

ERROR "POST /api/upload/ HTTP/1.1" 500 170854
ERROR Internal Server Error: /api/upload/
Traceback (most recent call last):
  File "/home/shinto/Documents/virtual_envs/rate_api/lib/python3.6/site-packages/django/db/backends/utils.py", line 84, in _execute
    return self.cursor.execute(sql, params)
psycopg2.errors.UndefinedTable: relation "api_prices" does not exist
LINE 1: INSERT INTO "api_prices" ("orig_code", "dest_code", "day", "...
                    ^


The above exception was the direct cause of the following exception:

Traceback (most recent call last):
  File "/home/shinto/Documents/virtual_envs/rate_api/lib/python3.6/site-packages/django/core/handlers/exception.py", line 34, in inner
    response = get_response(request)
  File "/home/shinto/Documents/virtual_envs/rate_api/lib/python3.6/site-packages/django/core/handlers/base.py", line 115, in _get_response
    response = self.process_exception_by_middleware(e, request)
  File "/home/shinto/Documents/virtual_envs/rate_api/lib/python3.6/site-packages/django/core/handlers/base.py", line 113, in _get_response
    response = wrapped_callback(request, *callback_args, **callback_kwargs)
  File "/home/shinto/Documents/virtual_envs/rate_api/lib/python3.6/site-packages/django/views/decorators/csrf.py", line 54, in wrapped_view
    return view_func(*args, **kwargs)
  File "/home/shinto/Documents/virtual_envs/rate_api/lib/python3.6/site-packages/django/views/generic/base.py", line 71, in view
    return self.dispatch(request, *args, **kwargs)
  File "/home/shinto/Documents/virtual_envs/rate_api/lib/python3.6/site-packages/rest_framework/views.py", line 495, in dispatch
    response = self.handle_exception(exc)
  File "/home/shinto/Documents/virtual_envs/rate_api/lib/python3.6/site-packages/rest_framework/views.py", line 455, in handle_exception
    self.raise_uncaught_exception(exc)
  File "/home/shinto/Documents/virtual_envs/rate_api/lib/python3.6/site-packages/rest_framework/views.py", line 492, in dispatch
    response = handler(request, *args, **kwargs)
  File "/home/shinto/Documents/projects/rate_project/rate_api/rate_api/api/views.py", line 264, in post
    p.save()
  File "/home/shinto/Documents/virtual_envs/rate_api/lib/python3.6/site-packages/django/db/models/base.py", line 741, in save
    force_update=force_update, update_fields=update_fields)
  File "/home/shinto/Documents/virtual_envs/rate_api/lib/python3.6/site-packages/django/db/models/base.py", line 779, in save_base
    force_update, using, update_fields,
  File "/home/shinto/Documents/virtual_envs/rate_api/lib/python3.6/site-packages/django/db/models/base.py", line 870, in _save_table
    result = self._do_insert(cls._base_manager, using, fields, update_pk, raw)
  File "/home/shinto/Documents/virtual_envs/rate_api/lib/python3.6/site-packages/django/db/models/base.py", line 908, in _do_insert
    using=using, raw=raw)
  File "/home/shinto/Documents/virtual_envs/rate_api/lib/python3.6/site-packages/django/db/models/manager.py", line 82, in manager_method
    return getattr(self.get_queryset(), name)(*args, **kwargs)
  File "/home/shinto/Documents/virtual_envs/rate_api/lib/python3.6/site-packages/django/db/models/query.py", line 1186, in _insert
    return query.get_compiler(using=using).execute_sql(return_id)
  File "/home/shinto/Documents/virtual_envs/rate_api/lib/python3.6/site-packages/django/db/models/sql/compiler.py", line 1335, in execute_sql
    cursor.execute(sql, params)
  File "/home/shinto/Documents/virtual_envs/rate_api/lib/python3.6/site-packages/django/db/backends/utils.py", line 99, in execute
    return super().execute(sql, params)
  File "/home/shinto/Documents/virtual_envs/rate_api/lib/python3.6/site-packages/django/db/backends/utils.py", line 67, in execute
    return self._execute_with_wrappers(sql, params, many=False, executor=self._execute)
  File "/home/shinto/Documents/virtual_envs/rate_api/lib/python3.6/site-packages/django/db/backends/utils.py", line 76, in _execute_with_wrappers
    return executor(sql, params, many, context)
  File "/home/shinto/Documents/virtual_envs/rate_api/lib/python3.6/site-packages/django/db/backends/utils.py", line 84, in _execute
    return self.cursor.execute(sql, params)
  File "/home/shinto/Documents/virtual_envs/rate_api/lib/python3.6/site-packages/django/db/utils.py", line 89, in __exit__
    raise dj_exc_value.with_traceback(traceback) from exc_value
  File "/home/shinto/Documents/virtual_envs/rate_api/lib/python3.6/site-packages/django/db/backends/utils.py", line 84, in _execute
    return self.cursor.execute(sql, params)
django.db.utils.ProgrammingError: relation "api_prices" does not exist
LINE 1: INSERT INTO "api_prices" ("orig_code", "dest_code", "day", "...
                    ^

ERROR "POST /api/upload/ HTTP/1.1" 500 170779
ERROR Internal Server Error: /api/upload/
Traceback (most recent call last):
  File "/home/shinto/Documents/virtual_envs/rate_api/lib/python3.6/site-packages/django/db/backends/utils.py", line 84, in _execute
    return self.cursor.execute(sql, params)
psycopg2.errors.UndefinedColumn: column api_prices.id does not exist
LINE 1: ...GGZ', 'EETLL', '2016-01-01'::date, 217) RETURNING "api_price...
                                                             ^


The above exception was the direct cause of the following exception:

Traceback (most recent call last):
  File "/home/shinto/Documents/virtual_envs/rate_api/lib/python3.6/site-packages/django/core/handlers/exception.py", line 34, in inner
    response = get_response(request)
  File "/home/shinto/Documents/virtual_envs/rate_api/lib/python3.6/site-packages/django/core/handlers/base.py", line 115, in _get_response
    response = self.process_exception_by_middleware(e, request)
  File "/home/shinto/Documents/virtual_envs/rate_api/lib/python3.6/site-packages/django/core/handlers/base.py", line 113, in _get_response
    response = wrapped_callback(request, *callback_args, **callback_kwargs)
  File "/home/shinto/Documents/virtual_envs/rate_api/lib/python3.6/site-packages/django/views/decorators/csrf.py", line 54, in wrapped_view
    return view_func(*args, **kwargs)
  File "/home/shinto/Documents/virtual_envs/rate_api/lib/python3.6/site-packages/django/views/generic/base.py", line 71, in view
    return self.dispatch(request, *args, **kwargs)
  File "/home/shinto/Documents/virtual_envs/rate_api/lib/python3.6/site-packages/rest_framework/views.py", line 495, in dispatch
    response = self.handle_exception(exc)
  File "/home/shinto/Documents/virtual_envs/rate_api/lib/python3.6/site-packages/rest_framework/views.py", line 455, in handle_exception
    self.raise_uncaught_exception(exc)
  File "/home/shinto/Documents/virtual_envs/rate_api/lib/python3.6/site-packages/rest_framework/views.py", line 492, in dispatch
    response = handler(request, *args, **kwargs)
  File "/home/shinto/Documents/projects/rate_project/rate_api/rate_api/api/views.py", line 264, in post
    p.save()
  File "/home/shinto/Documents/virtual_envs/rate_api/lib/python3.6/site-packages/django/db/models/base.py", line 741, in save
    force_update=force_update, update_fields=update_fields)
  File "/home/shinto/Documents/virtual_envs/rate_api/lib/python3.6/site-packages/django/db/models/base.py", line 779, in save_base
    force_update, using, update_fields,
  File "/home/shinto/Documents/virtual_envs/rate_api/lib/python3.6/site-packages/django/db/models/base.py", line 870, in _save_table
    result = self._do_insert(cls._base_manager, using, fields, update_pk, raw)
  File "/home/shinto/Documents/virtual_envs/rate_api/lib/python3.6/site-packages/django/db/models/base.py", line 908, in _do_insert
    using=using, raw=raw)
  File "/home/shinto/Documents/virtual_envs/rate_api/lib/python3.6/site-packages/django/db/models/manager.py", line 82, in manager_method
    return getattr(self.get_queryset(), name)(*args, **kwargs)
  File "/home/shinto/Documents/virtual_envs/rate_api/lib/python3.6/site-packages/django/db/models/query.py", line 1186, in _insert
    return query.get_compiler(using=using).execute_sql(return_id)
  File "/home/shinto/Documents/virtual_envs/rate_api/lib/python3.6/site-packages/django/db/models/sql/compiler.py", line 1335, in execute_sql
    cursor.execute(sql, params)
  File "/home/shinto/Documents/virtual_envs/rate_api/lib/python3.6/site-packages/django/db/backends/utils.py", line 99, in execute
    return super().execute(sql, params)
  File "/home/shinto/Documents/virtual_envs/rate_api/lib/python3.6/site-packages/django/db/backends/utils.py", line 67, in execute
    return self._execute_with_wrappers(sql, params, many=False, executor=self._execute)
  File "/home/shinto/Documents/virtual_envs/rate_api/lib/python3.6/site-packages/django/db/backends/utils.py", line 76, in _execute_with_wrappers
    return executor(sql, params, many, context)
  File "/home/shinto/Documents/virtual_envs/rate_api/lib/python3.6/site-packages/django/db/backends/utils.py", line 84, in _execute
    return self.cursor.execute(sql, params)
  File "/home/shinto/Documents/virtual_envs/rate_api/lib/python3.6/site-packages/django/db/utils.py", line 89, in __exit__
    raise dj_exc_value.with_traceback(traceback) from exc_value
  File "/home/shinto/Documents/virtual_envs/rate_api/lib/python3.6/site-packages/django/db/backends/utils.py", line 84, in _execute
    return self.cursor.execute(sql, params)
django.db.utils.ProgrammingError: column api_prices.id does not exist
LINE 1: ...GGZ', 'EETLL', '2016-01-01'::date, 217) RETURNING "api_price...
                                                             ^

ERROR "POST /api/upload/ HTTP/1.1" 500 170852
ERROR Internal Server Error: /api/upload/
Traceback (most recent call last):
  File "/home/shinto/Documents/virtual_envs/rate_api/lib/python3.6/site-packages/django/db/backends/utils.py", line 84, in _execute
    return self.cursor.execute(sql, params)
psycopg2.errors.UndefinedColumn: column api_prices.id does not exist
LINE 1: SELECT "api_prices"."id", "api_prices"."orig_code", "api_pri...
               ^


The above exception was the direct cause of the following exception:

Traceback (most recent call last):
  File "/home/shinto/Documents/virtual_envs/rate_api/lib/python3.6/site-packages/django/core/handlers/exception.py", line 34, in inner
    response = get_response(request)
  File "/home/shinto/Documents/virtual_envs/rate_api/lib/python3.6/site-packages/django/core/handlers/base.py", line 115, in _get_response
    response = self.process_exception_by_middleware(e, request)
  File "/home/shinto/Documents/virtual_envs/rate_api/lib/python3.6/site-packages/django/core/handlers/base.py", line 113, in _get_response
    response = wrapped_callback(request, *callback_args, **callback_kwargs)
  File "/home/shinto/Documents/virtual_envs/rate_api/lib/python3.6/site-packages/django/views/decorators/csrf.py", line 54, in wrapped_view
    return view_func(*args, **kwargs)
  File "/home/shinto/Documents/virtual_envs/rate_api/lib/python3.6/site-packages/django/views/generic/base.py", line 71, in view
    return self.dispatch(request, *args, **kwargs)
  File "/home/shinto/Documents/virtual_envs/rate_api/lib/python3.6/site-packages/rest_framework/views.py", line 495, in dispatch
    response = self.handle_exception(exc)
  File "/home/shinto/Documents/virtual_envs/rate_api/lib/python3.6/site-packages/rest_framework/views.py", line 455, in handle_exception
    self.raise_uncaught_exception(exc)
  File "/home/shinto/Documents/virtual_envs/rate_api/lib/python3.6/site-packages/rest_framework/views.py", line 492, in dispatch
    response = handler(request, *args, **kwargs)
  File "/home/shinto/Documents/projects/rate_project/rate_api/rate_api/api/views.py", line 257, in post
    for each in kk:
  File "/home/shinto/Documents/virtual_envs/rate_api/lib/python3.6/site-packages/django/db/models/query.py", line 274, in __iter__
    self._fetch_all()
  File "/home/shinto/Documents/virtual_envs/rate_api/lib/python3.6/site-packages/django/db/models/query.py", line 1242, in _fetch_all
    self._result_cache = list(self._iterable_class(self))
  File "/home/shinto/Documents/virtual_envs/rate_api/lib/python3.6/site-packages/django/db/models/query.py", line 55, in __iter__
    results = compiler.execute_sql(chunked_fetch=self.chunked_fetch, chunk_size=self.chunk_size)
  File "/home/shinto/Documents/virtual_envs/rate_api/lib/python3.6/site-packages/django/db/models/sql/compiler.py", line 1100, in execute_sql
    cursor.execute(sql, params)
  File "/home/shinto/Documents/virtual_envs/rate_api/lib/python3.6/site-packages/django/db/backends/utils.py", line 99, in execute
    return super().execute(sql, params)
  File "/home/shinto/Documents/virtual_envs/rate_api/lib/python3.6/site-packages/django/db/backends/utils.py", line 67, in execute
    return self._execute_with_wrappers(sql, params, many=False, executor=self._execute)
  File "/home/shinto/Documents/virtual_envs/rate_api/lib/python3.6/site-packages/django/db/backends/utils.py", line 76, in _execute_with_wrappers
    return executor(sql, params, many, context)
  File "/home/shinto/Documents/virtual_envs/rate_api/lib/python3.6/site-packages/django/db/backends/utils.py", line 84, in _execute
    return self.cursor.execute(sql, params)
  File "/home/shinto/Documents/virtual_envs/rate_api/lib/python3.6/site-packages/django/db/utils.py", line 89, in __exit__
    raise dj_exc_value.with_traceback(traceback) from exc_value
  File "/home/shinto/Documents/virtual_envs/rate_api/lib/python3.6/site-packages/django/db/backends/utils.py", line 84, in _execute
    return self.cursor.execute(sql, params)
django.db.utils.ProgrammingError: column api_prices.id does not exist
LINE 1: SELECT "api_prices"."id", "api_prices"."orig_code", "api_pri...
               ^

ERROR "POST /api/upload/ HTTP/1.1" 500 151107
ERROR Internal Server Error: /api/upload/
Traceback (most recent call last):
  File "/home/shinto/Documents/virtual_envs/rate_api/lib/python3.6/site-packages/django/db/backends/utils.py", line 84, in _execute
    return self.cursor.execute(sql, params)
  File "/home/shinto/Documents/virtual_envs/rate_api/lib/python3.6/site-packages/django/db/backends/sqlite3/base.py", line 383, in execute
    return Database.Cursor.execute(self, query, params)
sqlite3.OperationalError: no such column: api_prices.id

The above exception was the direct cause of the following exception:

Traceback (most recent call last):
  File "/home/shinto/Documents/virtual_envs/rate_api/lib/python3.6/site-packages/django/core/handlers/exception.py", line 34, in inner
    response = get_response(request)
  File "/home/shinto/Documents/virtual_envs/rate_api/lib/python3.6/site-packages/django/core/handlers/base.py", line 115, in _get_response
    response = self.process_exception_by_middleware(e, request)
  File "/home/shinto/Documents/virtual_envs/rate_api/lib/python3.6/site-packages/django/core/handlers/base.py", line 113, in _get_response
    response = wrapped_callback(request, *callback_args, **callback_kwargs)
  File "/home/shinto/Documents/virtual_envs/rate_api/lib/python3.6/site-packages/django/views/decorators/csrf.py", line 54, in wrapped_view
    return view_func(*args, **kwargs)
  File "/home/shinto/Documents/virtual_envs/rate_api/lib/python3.6/site-packages/django/views/generic/base.py", line 71, in view
    return self.dispatch(request, *args, **kwargs)
  File "/home/shinto/Documents/virtual_envs/rate_api/lib/python3.6/site-packages/rest_framework/views.py", line 495, in dispatch
    response = self.handle_exception(exc)
  File "/home/shinto/Documents/virtual_envs/rate_api/lib/python3.6/site-packages/rest_framework/views.py", line 455, in handle_exception
    self.raise_uncaught_exception(exc)
  File "/home/shinto/Documents/virtual_envs/rate_api/lib/python3.6/site-packages/rest_framework/views.py", line 492, in dispatch
    response = handler(request, *args, **kwargs)
  File "/home/shinto/Documents/projects/rate_project/rate_api/rate_api/api/views.py", line 257, in post
    for each in kk:
  File "/home/shinto/Documents/virtual_envs/rate_api/lib/python3.6/site-packages/django/db/models/query.py", line 274, in __iter__
    self._fetch_all()
  File "/home/shinto/Documents/virtual_envs/rate_api/lib/python3.6/site-packages/django/db/models/query.py", line 1242, in _fetch_all
    self._result_cache = list(self._iterable_class(self))
  File "/home/shinto/Documents/virtual_envs/rate_api/lib/python3.6/site-packages/django/db/models/query.py", line 55, in __iter__
    results = compiler.execute_sql(chunked_fetch=self.chunked_fetch, chunk_size=self.chunk_size)
  File "/home/shinto/Documents/virtual_envs/rate_api/lib/python3.6/site-packages/django/db/models/sql/compiler.py", line 1100, in execute_sql
    cursor.execute(sql, params)
  File "/home/shinto/Documents/virtual_envs/rate_api/lib/python3.6/site-packages/django/db/backends/utils.py", line 99, in execute
    return super().execute(sql, params)
  File "/home/shinto/Documents/virtual_envs/rate_api/lib/python3.6/site-packages/django/db/backends/utils.py", line 67, in execute
    return self._execute_with_wrappers(sql, params, many=False, executor=self._execute)
  File "/home/shinto/Documents/virtual_envs/rate_api/lib/python3.6/site-packages/django/db/backends/utils.py", line 76, in _execute_with_wrappers
    return executor(sql, params, many, context)
  File "/home/shinto/Documents/virtual_envs/rate_api/lib/python3.6/site-packages/django/db/backends/utils.py", line 84, in _execute
    return self.cursor.execute(sql, params)
  File "/home/shinto/Documents/virtual_envs/rate_api/lib/python3.6/site-packages/django/db/utils.py", line 89, in __exit__
    raise dj_exc_value.with_traceback(traceback) from exc_value
  File "/home/shinto/Documents/virtual_envs/rate_api/lib/python3.6/site-packages/django/db/backends/utils.py", line 84, in _execute
    return self.cursor.execute(sql, params)
  File "/home/shinto/Documents/virtual_envs/rate_api/lib/python3.6/site-packages/django/db/backends/sqlite3/base.py", line 383, in execute
    return Database.Cursor.execute(self, query, params)
django.db.utils.OperationalError: no such column: api_prices.id
ERROR "POST /api/upload/ HTTP/1.1" 500 158203
ERROR Internal Server Error: /api/upload/
Traceback (most recent call last):
  File "/home/shinto/Documents/virtual_envs/rate_api/lib/python3.6/site-packages/django/db/backends/utils.py", line 84, in _execute
    return self.cursor.execute(sql, params)
  File "/home/shinto/Documents/virtual_envs/rate_api/lib/python3.6/site-packages/django/db/backends/sqlite3/base.py", line 383, in execute
    return Database.Cursor.execute(self, query, params)
sqlite3.OperationalError: no such table: api_prices

The above exception was the direct cause of the following exception:

Traceback (most recent call last):
  File "/home/shinto/Documents/virtual_envs/rate_api/lib/python3.6/site-packages/django/core/handlers/exception.py", line 34, in inner
    response = get_response(request)
  File "/home/shinto/Documents/virtual_envs/rate_api/lib/python3.6/site-packages/django/core/handlers/base.py", line 115, in _get_response
    response = self.process_exception_by_middleware(e, request)
  File "/home/shinto/Documents/virtual_envs/rate_api/lib/python3.6/site-packages/django/core/handlers/base.py", line 113, in _get_response
    response = wrapped_callback(request, *callback_args, **callback_kwargs)
  File "/home/shinto/Documents/virtual_envs/rate_api/lib/python3.6/site-packages/django/views/decorators/csrf.py", line 54, in wrapped_view
    return view_func(*args, **kwargs)
  File "/home/shinto/Documents/virtual_envs/rate_api/lib/python3.6/site-packages/django/views/generic/base.py", line 71, in view
    return self.dispatch(request, *args, **kwargs)
  File "/home/shinto/Documents/virtual_envs/rate_api/lib/python3.6/site-packages/rest_framework/views.py", line 495, in dispatch
    response = self.handle_exception(exc)
  File "/home/shinto/Documents/virtual_envs/rate_api/lib/python3.6/site-packages/rest_framework/views.py", line 455, in handle_exception
    self.raise_uncaught_exception(exc)
  File "/home/shinto/Documents/virtual_envs/rate_api/lib/python3.6/site-packages/rest_framework/views.py", line 492, in dispatch
    response = handler(request, *args, **kwargs)
  File "/home/shinto/Documents/projects/rate_project/rate_api/rate_api/api/views.py", line 257, in post
    for each in kk:
  File "/home/shinto/Documents/virtual_envs/rate_api/lib/python3.6/site-packages/django/db/models/query.py", line 274, in __iter__
    self._fetch_all()
  File "/home/shinto/Documents/virtual_envs/rate_api/lib/python3.6/site-packages/django/db/models/query.py", line 1242, in _fetch_all
    self._result_cache = list(self._iterable_class(self))
  File "/home/shinto/Documents/virtual_envs/rate_api/lib/python3.6/site-packages/django/db/models/query.py", line 55, in __iter__
    results = compiler.execute_sql(chunked_fetch=self.chunked_fetch, chunk_size=self.chunk_size)
  File "/home/shinto/Documents/virtual_envs/rate_api/lib/python3.6/site-packages/django/db/models/sql/compiler.py", line 1100, in execute_sql
    cursor.execute(sql, params)
  File "/home/shinto/Documents/virtual_envs/rate_api/lib/python3.6/site-packages/django/db/backends/utils.py", line 99, in execute
    return super().execute(sql, params)
  File "/home/shinto/Documents/virtual_envs/rate_api/lib/python3.6/site-packages/django/db/backends/utils.py", line 67, in execute
    return self._execute_with_wrappers(sql, params, many=False, executor=self._execute)
  File "/home/shinto/Documents/virtual_envs/rate_api/lib/python3.6/site-packages/django/db/backends/utils.py", line 76, in _execute_with_wrappers
    return executor(sql, params, many, context)
  File "/home/shinto/Documents/virtual_envs/rate_api/lib/python3.6/site-packages/django/db/backends/utils.py", line 84, in _execute
    return self.cursor.execute(sql, params)
  File "/home/shinto/Documents/virtual_envs/rate_api/lib/python3.6/site-packages/django/db/utils.py", line 89, in __exit__
    raise dj_exc_value.with_traceback(traceback) from exc_value
  File "/home/shinto/Documents/virtual_envs/rate_api/lib/python3.6/site-packages/django/db/backends/utils.py", line 84, in _execute
    return self.cursor.execute(sql, params)
  File "/home/shinto/Documents/virtual_envs/rate_api/lib/python3.6/site-packages/django/db/backends/sqlite3/base.py", line 383, in execute
    return Database.Cursor.execute(self, query, params)
django.db.utils.OperationalError: no such table: api_prices
ERROR "POST /api/upload/ HTTP/1.1" 500 158151
ERROR Internal Server Error: /api/upload/
Traceback (most recent call last):
  File "/home/shinto/Documents/virtual_envs/rate_api/lib/python3.6/site-packages/django/core/handlers/exception.py", line 34, in inner
    response = get_response(request)
  File "/home/shinto/Documents/virtual_envs/rate_api/lib/python3.6/site-packages/django/core/handlers/base.py", line 115, in _get_response
    response = self.process_exception_by_middleware(e, request)
  File "/home/shinto/Documents/virtual_envs/rate_api/lib/python3.6/site-packages/django/core/handlers/base.py", line 113, in _get_response
    response = wrapped_callback(request, *callback_args, **callback_kwargs)
  File "/home/shinto/Documents/virtual_envs/rate_api/lib/python3.6/site-packages/django/views/decorators/csrf.py", line 54, in wrapped_view
    return view_func(*args, **kwargs)
  File "/home/shinto/Documents/virtual_envs/rate_api/lib/python3.6/site-packages/django/views/generic/base.py", line 71, in view
    return self.dispatch(request, *args, **kwargs)
  File "/home/shinto/Documents/virtual_envs/rate_api/lib/python3.6/site-packages/rest_framework/views.py", line 495, in dispatch
    response = self.handle_exception(exc)
  File "/home/shinto/Documents/virtual_envs/rate_api/lib/python3.6/site-packages/rest_framework/views.py", line 455, in handle_exception
    self.raise_uncaught_exception(exc)
  File "/home/shinto/Documents/virtual_envs/rate_api/lib/python3.6/site-packages/rest_framework/views.py", line 492, in dispatch
    response = handler(request, *args, **kwargs)
  File "/home/shinto/Documents/projects/rate_project/rate_api/rate_api/api/views.py", line 256, in post
    person, created = Person.objects.get_or_create(identifier=id)
NameError: name 'Person' is not defined
ERROR "POST /api/upload/ HTTP/1.1" 500 17523
ERROR Internal Server Error: /api/upload/
Traceback (most recent call last):
  File "/home/shinto/Documents/virtual_envs/rate_api/lib/python3.6/site-packages/django/core/handlers/exception.py", line 34, in inner
    response = get_response(request)
  File "/home/shinto/Documents/virtual_envs/rate_api/lib/python3.6/site-packages/django/core/handlers/base.py", line 115, in _get_response
    response = self.process_exception_by_middleware(e, request)
  File "/home/shinto/Documents/virtual_envs/rate_api/lib/python3.6/site-packages/django/core/handlers/base.py", line 113, in _get_response
    response = wrapped_callback(request, *callback_args, **callback_kwargs)
  File "/home/shinto/Documents/virtual_envs/rate_api/lib/python3.6/site-packages/django/views/decorators/csrf.py", line 54, in wrapped_view
    return view_func(*args, **kwargs)
  File "/home/shinto/Documents/virtual_envs/rate_api/lib/python3.6/site-packages/django/views/generic/base.py", line 71, in view
    return self.dispatch(request, *args, **kwargs)
  File "/home/shinto/Documents/virtual_envs/rate_api/lib/python3.6/site-packages/rest_framework/views.py", line 495, in dispatch
    response = self.handle_exception(exc)
  File "/home/shinto/Documents/virtual_envs/rate_api/lib/python3.6/site-packages/rest_framework/views.py", line 455, in handle_exception
    self.raise_uncaught_exception(exc)
  File "/home/shinto/Documents/virtual_envs/rate_api/lib/python3.6/site-packages/rest_framework/views.py", line 492, in dispatch
    response = handler(request, *args, **kwargs)
  File "/home/shinto/Documents/projects/rate_project/rate_api/rate_api/api/views.py", line 262, in post
    price       = price)
  File "/home/shinto/Documents/virtual_envs/rate_api/lib/python3.6/site-packages/django/db/models/manager.py", line 82, in manager_method
    return getattr(self.get_queryset(), name)(*args, **kwargs)
  File "/home/shinto/Documents/virtual_envs/rate_api/lib/python3.6/site-packages/django/db/models/query.py", line 538, in get_or_create
    return self.get(**kwargs), False
  File "/home/shinto/Documents/virtual_envs/rate_api/lib/python3.6/site-packages/django/db/models/query.py", line 412, in get
    (self.model._meta.object_name, num)
api.models.Prices.MultipleObjectsReturned: get() returned more than one Prices -- it returned 3!
ERROR "POST /api/upload/ HTTP/1.1" 500 18151
ERROR Internal Server Error: /api/upload/
Traceback (most recent call last):
  File "/home/shinto/Documents/virtual_envs/rate_api/lib/python3.6/site-packages/django/core/handlers/exception.py", line 34, in inner
    response = get_response(request)
  File "/home/shinto/Documents/virtual_envs/rate_api/lib/python3.6/site-packages/django/core/handlers/base.py", line 115, in _get_response
    response = self.process_exception_by_middleware(e, request)
  File "/home/shinto/Documents/virtual_envs/rate_api/lib/python3.6/site-packages/django/core/handlers/base.py", line 113, in _get_response
    response = wrapped_callback(request, *callback_args, **callback_kwargs)
  File "/home/shinto/Documents/virtual_envs/rate_api/lib/python3.6/site-packages/django/views/decorators/csrf.py", line 54, in wrapped_view
    return view_func(*args, **kwargs)
  File "/home/shinto/Documents/virtual_envs/rate_api/lib/python3.6/site-packages/django/views/generic/base.py", line 71, in view
    return self.dispatch(request, *args, **kwargs)
  File "/home/shinto/Documents/virtual_envs/rate_api/lib/python3.6/site-packages/rest_framework/views.py", line 495, in dispatch
    response = self.handle_exception(exc)
  File "/home/shinto/Documents/virtual_envs/rate_api/lib/python3.6/site-packages/rest_framework/views.py", line 455, in handle_exception
    self.raise_uncaught_exception(exc)
  File "/home/shinto/Documents/virtual_envs/rate_api/lib/python3.6/site-packages/rest_framework/views.py", line 492, in dispatch
    response = handler(request, *args, **kwargs)
  File "/home/shinto/Documents/projects/rate_project/rate_api/rate_api/api/views.py", line 264, in post
    p.save()
AttributeError: 'tuple' object has no attribute 'save'
ERROR "POST /api/upload/ HTTP/1.1" 500 17504
ERROR Internal Server Error: /api/rates/2016-01-01/2016-01-02/CNGGZ/EETLL/
Traceback (most recent call last):
  File "/home/shinto/Documents/virtual_envs/rate_api/lib/python3.6/site-packages/pandas/core/indexes/base.py", line 2657, in get_loc
    return self._engine.get_loc(key)
  File "pandas/_libs/index.pyx", line 108, in pandas._libs.index.IndexEngine.get_loc
  File "pandas/_libs/index.pyx", line 129, in pandas._libs.index.IndexEngine.get_loc
  File "pandas/_libs/index_class_helper.pxi", line 91, in pandas._libs.index.Int64Engine._check_type
KeyError: 'day'

During handling of the above exception, another exception occurred:

Traceback (most recent call last):
  File "/home/shinto/Documents/virtual_envs/rate_api/lib/python3.6/site-packages/django/core/handlers/exception.py", line 34, in inner
    response = get_response(request)
  File "/home/shinto/Documents/virtual_envs/rate_api/lib/python3.6/site-packages/django/core/handlers/base.py", line 115, in _get_response
    response = self.process_exception_by_middleware(e, request)
  File "/home/shinto/Documents/virtual_envs/rate_api/lib/python3.6/site-packages/django/core/handlers/base.py", line 113, in _get_response
    response = wrapped_callback(request, *callback_args, **callback_kwargs)
  File "/home/shinto/Documents/virtual_envs/rate_api/lib/python3.6/site-packages/django/views/decorators/csrf.py", line 54, in wrapped_view
    return view_func(*args, **kwargs)
  File "/home/shinto/Documents/virtual_envs/rate_api/lib/python3.6/site-packages/django/views/generic/base.py", line 71, in view
    return self.dispatch(request, *args, **kwargs)
  File "/home/shinto/Documents/virtual_envs/rate_api/lib/python3.6/site-packages/rest_framework/views.py", line 495, in dispatch
    response = self.handle_exception(exc)
  File "/home/shinto/Documents/virtual_envs/rate_api/lib/python3.6/site-packages/rest_framework/views.py", line 455, in handle_exception
    self.raise_uncaught_exception(exc)
  File "/home/shinto/Documents/virtual_envs/rate_api/lib/python3.6/site-packages/rest_framework/views.py", line 492, in dispatch
    response = handler(request, *args, **kwargs)
  File "/home/shinto/Documents/virtual_envs/rate_api/lib/python3.6/site-packages/rest_framework/decorators.py", line 55, in handler
    return func(*args, **kwargs)
  File "/home/shinto/Documents/projects/rate_project/rate_api/rate_api/api/views.py", line 164, in rates
    mean_df = df.groupby(df['day']).mean().astype(int)
  File "/home/shinto/Documents/virtual_envs/rate_api/lib/python3.6/site-packages/pandas/core/frame.py", line 2927, in __getitem__
    indexer = self.columns.get_loc(key)
  File "/home/shinto/Documents/virtual_envs/rate_api/lib/python3.6/site-packages/pandas/core/indexes/base.py", line 2659, in get_loc
    return self._engine.get_loc(self._maybe_cast_indexer(key))
  File "pandas/_libs/index.pyx", line 108, in pandas._libs.index.IndexEngine.get_loc
  File "pandas/_libs/index.pyx", line 129, in pandas._libs.index.IndexEngine.get_loc
  File "pandas/_libs/index_class_helper.pxi", line 91, in pandas._libs.index.Int64Engine._check_type
KeyError: 'day'
ERROR "GET /api/rates/2016-01-01/2016-01-02/CNGGZ/EETLL/ HTTP/1.1" 500 19066
ERROR Internal Server Error: /api/upload/
Traceback (most recent call last):
  File "/home/shinto/Documents/virtual_envs/rate_api/lib/python3.6/site-packages/django/core/handlers/exception.py", line 34, in inner
    response = get_response(request)
  File "/home/shinto/Documents/virtual_envs/rate_api/lib/python3.6/site-packages/django/core/handlers/base.py", line 115, in _get_response
    response = self.process_exception_by_middleware(e, request)
  File "/home/shinto/Documents/virtual_envs/rate_api/lib/python3.6/site-packages/django/core/handlers/base.py", line 113, in _get_response
    response = wrapped_callback(request, *callback_args, **callback_kwargs)
  File "/home/shinto/Documents/virtual_envs/rate_api/lib/python3.6/site-packages/django/views/decorators/csrf.py", line 54, in wrapped_view
    return view_func(*args, **kwargs)
  File "/home/shinto/Documents/virtual_envs/rate_api/lib/python3.6/site-packages/django/views/generic/base.py", line 71, in view
    return self.dispatch(request, *args, **kwargs)
  File "/home/shinto/Documents/virtual_envs/rate_api/lib/python3.6/site-packages/rest_framework/views.py", line 495, in dispatch
    response = self.handle_exception(exc)
  File "/home/shinto/Documents/virtual_envs/rate_api/lib/python3.6/site-packages/rest_framework/views.py", line 455, in handle_exception
    self.raise_uncaught_exception(exc)
  File "/home/shinto/Documents/virtual_envs/rate_api/lib/python3.6/site-packages/rest_framework/views.py", line 492, in dispatch
    response = handler(request, *args, **kwargs)
  File "/home/shinto/Documents/projects/rate_project/rate_api/rate_api/api/views.py", line 265, in post
    day         = date,
  File "/home/shinto/Documents/virtual_envs/rate_api/lib/python3.6/site-packages/django/db/models/manager.py", line 82, in manager_method
    return getattr(self.get_queryset(), name)(*args, **kwargs)
  File "/home/shinto/Documents/virtual_envs/rate_api/lib/python3.6/site-packages/django/db/models/query.py", line 538, in get_or_create
    return self.get(**kwargs), False
  File "/home/shinto/Documents/virtual_envs/rate_api/lib/python3.6/site-packages/django/db/models/query.py", line 412, in get
    (self.model._meta.object_name, num)
api.models.Prices.MultipleObjectsReturned: get() returned more than one Prices -- it returned 2!
ERROR "POST /api/upload/ HTTP/1.1" 500 18150
ERROR Internal Server Error: /api/upload/
Traceback (most recent call last):
  File "/home/shinto/Documents/virtual_envs/rate_api/lib/python3.6/site-packages/django/db/models/query.py", line 538, in get_or_create
    return self.get(**kwargs), False
  File "/home/shinto/Documents/virtual_envs/rate_api/lib/python3.6/site-packages/django/db/models/query.py", line 408, in get
    self.model._meta.object_name
api.models.Prices.DoesNotExist: Prices matching query does not exist.

During handling of the above exception, another exception occurred:

Traceback (most recent call last):
  File "/home/shinto/Documents/virtual_envs/rate_api/lib/python3.6/site-packages/django/db/backends/utils.py", line 84, in _execute
    return self.cursor.execute(sql, params)
  File "/home/shinto/Documents/virtual_envs/rate_api/lib/python3.6/site-packages/django/db/backends/sqlite3/base.py", line 383, in execute
    return Database.Cursor.execute(self, query, params)
sqlite3.IntegrityError: NOT NULL constraint failed: api_prices.price

The above exception was the direct cause of the following exception:

Traceback (most recent call last):
  File "/home/shinto/Documents/virtual_envs/rate_api/lib/python3.6/site-packages/django/core/handlers/exception.py", line 34, in inner
    response = get_response(request)
  File "/home/shinto/Documents/virtual_envs/rate_api/lib/python3.6/site-packages/django/core/handlers/base.py", line 115, in _get_response
    response = self.process_exception_by_middleware(e, request)
  File "/home/shinto/Documents/virtual_envs/rate_api/lib/python3.6/site-packages/django/core/handlers/base.py", line 113, in _get_response
    response = wrapped_callback(request, *callback_args, **callback_kwargs)
  File "/home/shinto/Documents/virtual_envs/rate_api/lib/python3.6/site-packages/django/views/decorators/csrf.py", line 54, in wrapped_view
    return view_func(*args, **kwargs)
  File "/home/shinto/Documents/virtual_envs/rate_api/lib/python3.6/site-packages/django/views/generic/base.py", line 71, in view
    return self.dispatch(request, *args, **kwargs)
  File "/home/shinto/Documents/virtual_envs/rate_api/lib/python3.6/site-packages/rest_framework/views.py", line 495, in dispatch
    response = self.handle_exception(exc)
  File "/home/shinto/Documents/virtual_envs/rate_api/lib/python3.6/site-packages/rest_framework/views.py", line 455, in handle_exception
    self.raise_uncaught_exception(exc)
  File "/home/shinto/Documents/virtual_envs/rate_api/lib/python3.6/site-packages/rest_framework/views.py", line 492, in dispatch
    response = handler(request, *args, **kwargs)
  File "/home/shinto/Documents/projects/rate_project/rate_api/rate_api/api/views.py", line 266, in post
    day         = date,
  File "/home/shinto/Documents/virtual_envs/rate_api/lib/python3.6/site-packages/django/db/models/manager.py", line 82, in manager_method
    return getattr(self.get_queryset(), name)(*args, **kwargs)
  File "/home/shinto/Documents/virtual_envs/rate_api/lib/python3.6/site-packages/django/db/models/query.py", line 541, in get_or_create
    return self._create_object_from_params(kwargs, params)
  File "/home/shinto/Documents/virtual_envs/rate_api/lib/python3.6/site-packages/django/db/models/query.py", line 583, in _create_object_from_params
    raise e
  File "/home/shinto/Documents/virtual_envs/rate_api/lib/python3.6/site-packages/django/db/models/query.py", line 575, in _create_object_from_params
    obj = self.create(**params)
  File "/home/shinto/Documents/virtual_envs/rate_api/lib/python3.6/site-packages/django/db/models/query.py", line 422, in create
    obj.save(force_insert=True, using=self.db)
  File "/home/shinto/Documents/virtual_envs/rate_api/lib/python3.6/site-packages/django/db/models/base.py", line 741, in save
    force_update=force_update, update_fields=update_fields)
  File "/home/shinto/Documents/virtual_envs/rate_api/lib/python3.6/site-packages/django/db/models/base.py", line 779, in save_base
    force_update, using, update_fields,
  File "/home/shinto/Documents/virtual_envs/rate_api/lib/python3.6/site-packages/django/db/models/base.py", line 870, in _save_table
    result = self._do_insert(cls._base_manager, using, fields, update_pk, raw)
  File "/home/shinto/Documents/virtual_envs/rate_api/lib/python3.6/site-packages/django/db/models/base.py", line 908, in _do_insert
    using=using, raw=raw)
  File "/home/shinto/Documents/virtual_envs/rate_api/lib/python3.6/site-packages/django/db/models/manager.py", line 82, in manager_method
    return getattr(self.get_queryset(), name)(*args, **kwargs)
  File "/home/shinto/Documents/virtual_envs/rate_api/lib/python3.6/site-packages/django/db/models/query.py", line 1186, in _insert
    return query.get_compiler(using=using).execute_sql(return_id)
  File "/home/shinto/Documents/virtual_envs/rate_api/lib/python3.6/site-packages/django/db/models/sql/compiler.py", line 1335, in execute_sql
    cursor.execute(sql, params)
  File "/home/shinto/Documents/virtual_envs/rate_api/lib/python3.6/site-packages/django/db/backends/utils.py", line 99, in execute
    return super().execute(sql, params)
  File "/home/shinto/Documents/virtual_envs/rate_api/lib/python3.6/site-packages/django/db/backends/utils.py", line 67, in execute
    return self._execute_with_wrappers(sql, params, many=False, executor=self._execute)
  File "/home/shinto/Documents/virtual_envs/rate_api/lib/python3.6/site-packages/django/db/backends/utils.py", line 76, in _execute_with_wrappers
    return executor(sql, params, many, context)
  File "/home/shinto/Documents/virtual_envs/rate_api/lib/python3.6/site-packages/django/db/backends/utils.py", line 84, in _execute
    return self.cursor.execute(sql, params)
  File "/home/shinto/Documents/virtual_envs/rate_api/lib/python3.6/site-packages/django/db/utils.py", line 89, in __exit__
    raise dj_exc_value.with_traceback(traceback) from exc_value
  File "/home/shinto/Documents/virtual_envs/rate_api/lib/python3.6/site-packages/django/db/backends/utils.py", line 84, in _execute
    return self.cursor.execute(sql, params)
  File "/home/shinto/Documents/virtual_envs/rate_api/lib/python3.6/site-packages/django/db/backends/sqlite3/base.py", line 383, in execute
    return Database.Cursor.execute(self, query, params)
django.db.utils.IntegrityError: NOT NULL constraint failed: api_prices.price
ERROR "POST /api/upload/ HTTP/1.1" 500 22136
ERROR Internal Server Error: /api/rates_null/2016-01-01/2016-01-10/CNSGH/north_europe_main/
Traceback (most recent call last):
  File "/home/shinto/Documents/virtual_envs/rate_api/lib/python3.6/site-packages/pandas/core/indexes/base.py", line 2657, in get_loc
    return self._engine.get_loc(key)
  File "pandas/_libs/index.pyx", line 108, in pandas._libs.index.IndexEngine.get_loc
  File "pandas/_libs/index.pyx", line 132, in pandas._libs.index.IndexEngine.get_loc
  File "pandas/_libs/hashtable_class_helper.pxi", line 1601, in pandas._libs.hashtable.PyObjectHashTable.get_item
  File "pandas/_libs/hashtable_class_helper.pxi", line 1608, in pandas._libs.hashtable.PyObjectHashTable.get_item
KeyError: 'day'

During handling of the above exception, another exception occurred:

Traceback (most recent call last):
  File "/home/shinto/Documents/virtual_envs/rate_api/lib/python3.6/site-packages/django/core/handlers/exception.py", line 34, in inner
    response = get_response(request)
  File "/home/shinto/Documents/virtual_envs/rate_api/lib/python3.6/site-packages/django/core/handlers/base.py", line 115, in _get_response
    response = self.process_exception_by_middleware(e, request)
  File "/home/shinto/Documents/virtual_envs/rate_api/lib/python3.6/site-packages/django/core/handlers/base.py", line 113, in _get_response
    response = wrapped_callback(request, *callback_args, **callback_kwargs)
  File "/home/shinto/Documents/virtual_envs/rate_api/lib/python3.6/site-packages/django/views/decorators/csrf.py", line 54, in wrapped_view
    return view_func(*args, **kwargs)
  File "/home/shinto/Documents/virtual_envs/rate_api/lib/python3.6/site-packages/django/views/generic/base.py", line 71, in view
    return self.dispatch(request, *args, **kwargs)
  File "/home/shinto/Documents/virtual_envs/rate_api/lib/python3.6/site-packages/rest_framework/views.py", line 495, in dispatch
    response = self.handle_exception(exc)
  File "/home/shinto/Documents/virtual_envs/rate_api/lib/python3.6/site-packages/rest_framework/views.py", line 455, in handle_exception
    self.raise_uncaught_exception(exc)
  File "/home/shinto/Documents/virtual_envs/rate_api/lib/python3.6/site-packages/rest_framework/views.py", line 492, in dispatch
    response = handler(request, *args, **kwargs)
  File "/home/shinto/Documents/virtual_envs/rate_api/lib/python3.6/site-packages/rest_framework/decorators.py", line 55, in handler
    return func(*args, **kwargs)
  File "/home/shinto/Documents/projects/rate_project/rate_api/rate_api/api/views.py", line 200, in rates_null
    df = pd.DataFrame(list(filtered_queryset.values('day', 'price'))).set_index('day')
  File "/home/shinto/Documents/virtual_envs/rate_api/lib/python3.6/site-packages/pandas/core/frame.py", line 4178, in set_index
    level = frame[col]._values
  File "/home/shinto/Documents/virtual_envs/rate_api/lib/python3.6/site-packages/pandas/core/frame.py", line 2927, in __getitem__
    indexer = self.columns.get_loc(key)
  File "/home/shinto/Documents/virtual_envs/rate_api/lib/python3.6/site-packages/pandas/core/indexes/base.py", line 2659, in get_loc
    return self._engine.get_loc(self._maybe_cast_indexer(key))
  File "pandas/_libs/index.pyx", line 108, in pandas._libs.index.IndexEngine.get_loc
  File "pandas/_libs/index.pyx", line 132, in pandas._libs.index.IndexEngine.get_loc
  File "pandas/_libs/hashtable_class_helper.pxi", line 1601, in pandas._libs.hashtable.PyObjectHashTable.get_item
  File "pandas/_libs/hashtable_class_helper.pxi", line 1608, in pandas._libs.hashtable.PyObjectHashTable.get_item
KeyError: 'day'
ERROR "GET /api/rates_null/2016-01-01/2016-01-10/CNSGH/north_europe_main/ HTTP/1.1" 500 19637
ERROR Internal Server Error: /api/rates_null/2016-01-01/2016-01-10/CNSGH/north_europe_main/
Traceback (most recent call last):
  File "/home/shinto/Documents/virtual_envs/rate_api/lib/python3.6/site-packages/pandas/core/indexes/base.py", line 2657, in get_loc
    return self._engine.get_loc(key)
  File "pandas/_libs/index.pyx", line 108, in pandas._libs.index.IndexEngine.get_loc
  File "pandas/_libs/index.pyx", line 132, in pandas._libs.index.IndexEngine.get_loc
  File "pandas/_libs/hashtable_class_helper.pxi", line 1601, in pandas._libs.hashtable.PyObjectHashTable.get_item
  File "pandas/_libs/hashtable_class_helper.pxi", line 1608, in pandas._libs.hashtable.PyObjectHashTable.get_item
KeyError: 'day'

During handling of the above exception, another exception occurred:

Traceback (most recent call last):
  File "/home/shinto/Documents/virtual_envs/rate_api/lib/python3.6/site-packages/django/core/handlers/exception.py", line 34, in inner
    response = get_response(request)
  File "/home/shinto/Documents/virtual_envs/rate_api/lib/python3.6/site-packages/django/core/handlers/base.py", line 115, in _get_response
    response = self.process_exception_by_middleware(e, request)
  File "/home/shinto/Documents/virtual_envs/rate_api/lib/python3.6/site-packages/django/core/handlers/base.py", line 113, in _get_response
    response = wrapped_callback(request, *callback_args, **callback_kwargs)
  File "/home/shinto/Documents/virtual_envs/rate_api/lib/python3.6/site-packages/django/views/decorators/csrf.py", line 54, in wrapped_view
    return view_func(*args, **kwargs)
  File "/home/shinto/Documents/virtual_envs/rate_api/lib/python3.6/site-packages/django/views/generic/base.py", line 71, in view
    return self.dispatch(request, *args, **kwargs)
  File "/home/shinto/Documents/virtual_envs/rate_api/lib/python3.6/site-packages/rest_framework/views.py", line 495, in dispatch
    response = self.handle_exception(exc)
  File "/home/shinto/Documents/virtual_envs/rate_api/lib/python3.6/site-packages/rest_framework/views.py", line 455, in handle_exception
    self.raise_uncaught_exception(exc)
  File "/home/shinto/Documents/virtual_envs/rate_api/lib/python3.6/site-packages/rest_framework/views.py", line 492, in dispatch
    response = handler(request, *args, **kwargs)
  File "/home/shinto/Documents/virtual_envs/rate_api/lib/python3.6/site-packages/rest_framework/decorators.py", line 55, in handler
    return func(*args, **kwargs)
  File "/home/shinto/Documents/projects/rate_project/rate_api/rate_api/api/views.py", line 200, in rates_null
    df = pd.DataFrame(list(filtered_queryset.values('day', 'price'))).set_index('day')
  File "/home/shinto/Documents/virtual_envs/rate_api/lib/python3.6/site-packages/pandas/core/frame.py", line 4178, in set_index
    level = frame[col]._values
  File "/home/shinto/Documents/virtual_envs/rate_api/lib/python3.6/site-packages/pandas/core/frame.py", line 2927, in __getitem__
    indexer = self.columns.get_loc(key)
  File "/home/shinto/Documents/virtual_envs/rate_api/lib/python3.6/site-packages/pandas/core/indexes/base.py", line 2659, in get_loc
    return self._engine.get_loc(self._maybe_cast_indexer(key))
  File "pandas/_libs/index.pyx", line 108, in pandas._libs.index.IndexEngine.get_loc
  File "pandas/_libs/index.pyx", line 132, in pandas._libs.index.IndexEngine.get_loc
  File "pandas/_libs/hashtable_class_helper.pxi", line 1601, in pandas._libs.hashtable.PyObjectHashTable.get_item
  File "pandas/_libs/hashtable_class_helper.pxi", line 1608, in pandas._libs.hashtable.PyObjectHashTable.get_item
KeyError: 'day'
ERROR "GET /api/rates_null/2016-01-01/2016-01-10/CNSGH/north_europe_main/ HTTP/1.1" 500 19637
ERROR Internal Server Error: /api/rates_null/2016-01-01/2016-01-10/CNSGH/north_europe_main/
Traceback (most recent call last):
  File "/home/shinto/Documents/virtual_envs/rate_api/lib/python3.6/site-packages/pandas/core/indexes/base.py", line 2657, in get_loc
    return self._engine.get_loc(key)
  File "pandas/_libs/index.pyx", line 108, in pandas._libs.index.IndexEngine.get_loc
  File "pandas/_libs/index.pyx", line 132, in pandas._libs.index.IndexEngine.get_loc
  File "pandas/_libs/hashtable_class_helper.pxi", line 1601, in pandas._libs.hashtable.PyObjectHashTable.get_item
  File "pandas/_libs/hashtable_class_helper.pxi", line 1608, in pandas._libs.hashtable.PyObjectHashTable.get_item
KeyError: 'day'

During handling of the above exception, another exception occurred:

Traceback (most recent call last):
  File "/home/shinto/Documents/virtual_envs/rate_api/lib/python3.6/site-packages/django/core/handlers/exception.py", line 34, in inner
    response = get_response(request)
  File "/home/shinto/Documents/virtual_envs/rate_api/lib/python3.6/site-packages/django/core/handlers/base.py", line 115, in _get_response
    response = self.process_exception_by_middleware(e, request)
  File "/home/shinto/Documents/virtual_envs/rate_api/lib/python3.6/site-packages/django/core/handlers/base.py", line 113, in _get_response
    response = wrapped_callback(request, *callback_args, **callback_kwargs)
  File "/home/shinto/Documents/virtual_envs/rate_api/lib/python3.6/site-packages/django/views/decorators/csrf.py", line 54, in wrapped_view
    return view_func(*args, **kwargs)
  File "/home/shinto/Documents/virtual_envs/rate_api/lib/python3.6/site-packages/django/views/generic/base.py", line 71, in view
    return self.dispatch(request, *args, **kwargs)
  File "/home/shinto/Documents/virtual_envs/rate_api/lib/python3.6/site-packages/rest_framework/views.py", line 495, in dispatch
    response = self.handle_exception(exc)
  File "/home/shinto/Documents/virtual_envs/rate_api/lib/python3.6/site-packages/rest_framework/views.py", line 455, in handle_exception
    self.raise_uncaught_exception(exc)
  File "/home/shinto/Documents/virtual_envs/rate_api/lib/python3.6/site-packages/rest_framework/views.py", line 492, in dispatch
    response = handler(request, *args, **kwargs)
  File "/home/shinto/Documents/virtual_envs/rate_api/lib/python3.6/site-packages/rest_framework/decorators.py", line 55, in handler
    return func(*args, **kwargs)
  File "/home/shinto/Documents/projects/rate_project/rate_api/rate_api/api/views.py", line 201, in rates_null
    df = pd.DataFrame(list(filtered_queryset.values('day', 'price'))).set_index('day')
  File "/home/shinto/Documents/virtual_envs/rate_api/lib/python3.6/site-packages/pandas/core/frame.py", line 4178, in set_index
    level = frame[col]._values
  File "/home/shinto/Documents/virtual_envs/rate_api/lib/python3.6/site-packages/pandas/core/frame.py", line 2927, in __getitem__
    indexer = self.columns.get_loc(key)
  File "/home/shinto/Documents/virtual_envs/rate_api/lib/python3.6/site-packages/pandas/core/indexes/base.py", line 2659, in get_loc
    return self._engine.get_loc(self._maybe_cast_indexer(key))
  File "pandas/_libs/index.pyx", line 108, in pandas._libs.index.IndexEngine.get_loc
  File "pandas/_libs/index.pyx", line 132, in pandas._libs.index.IndexEngine.get_loc
  File "pandas/_libs/hashtable_class_helper.pxi", line 1601, in pandas._libs.hashtable.PyObjectHashTable.get_item
  File "pandas/_libs/hashtable_class_helper.pxi", line 1608, in pandas._libs.hashtable.PyObjectHashTable.get_item
KeyError: 'day'
ERROR "GET /api/rates_null/2016-01-01/2016-01-10/CNSGH/north_europe_main/ HTTP/1.1" 500 19637
ERROR Internal Server Error: /api/rates_null/2016-01-01/2016-01-10/CNSGH/north_europe_main/
Traceback (most recent call last):
  File "/home/shinto/Documents/virtual_envs/rate_api/lib/python3.6/site-packages/pandas/core/indexes/base.py", line 2657, in get_loc
    return self._engine.get_loc(key)
  File "pandas/_libs/index.pyx", line 108, in pandas._libs.index.IndexEngine.get_loc
  File "pandas/_libs/index.pyx", line 132, in pandas._libs.index.IndexEngine.get_loc
  File "pandas/_libs/hashtable_class_helper.pxi", line 1601, in pandas._libs.hashtable.PyObjectHashTable.get_item
  File "pandas/_libs/hashtable_class_helper.pxi", line 1608, in pandas._libs.hashtable.PyObjectHashTable.get_item
KeyError: 'day'

During handling of the above exception, another exception occurred:

Traceback (most recent call last):
  File "/home/shinto/Documents/virtual_envs/rate_api/lib/python3.6/site-packages/django/core/handlers/exception.py", line 34, in inner
    response = get_response(request)
  File "/home/shinto/Documents/virtual_envs/rate_api/lib/python3.6/site-packages/django/core/handlers/base.py", line 115, in _get_response
    response = self.process_exception_by_middleware(e, request)
  File "/home/shinto/Documents/virtual_envs/rate_api/lib/python3.6/site-packages/django/core/handlers/base.py", line 113, in _get_response
    response = wrapped_callback(request, *callback_args, **callback_kwargs)
  File "/home/shinto/Documents/virtual_envs/rate_api/lib/python3.6/site-packages/django/views/decorators/csrf.py", line 54, in wrapped_view
    return view_func(*args, **kwargs)
  File "/home/shinto/Documents/virtual_envs/rate_api/lib/python3.6/site-packages/django/views/generic/base.py", line 71, in view
    return self.dispatch(request, *args, **kwargs)
  File "/home/shinto/Documents/virtual_envs/rate_api/lib/python3.6/site-packages/rest_framework/views.py", line 495, in dispatch
    response = self.handle_exception(exc)
  File "/home/shinto/Documents/virtual_envs/rate_api/lib/python3.6/site-packages/rest_framework/views.py", line 455, in handle_exception
    self.raise_uncaught_exception(exc)
  File "/home/shinto/Documents/virtual_envs/rate_api/lib/python3.6/site-packages/rest_framework/views.py", line 492, in dispatch
    response = handler(request, *args, **kwargs)
  File "/home/shinto/Documents/virtual_envs/rate_api/lib/python3.6/site-packages/rest_framework/decorators.py", line 55, in handler
    return func(*args, **kwargs)
  File "/home/shinto/Documents/projects/rate_project/rate_api/rate_api/api/views.py", line 201, in rates_null
    df = pd.DataFrame(list(filtered_queryset.values('day', 'price'))).set_index('day')
  File "/home/shinto/Documents/virtual_envs/rate_api/lib/python3.6/site-packages/pandas/core/frame.py", line 4178, in set_index
    level = frame[col]._values
  File "/home/shinto/Documents/virtual_envs/rate_api/lib/python3.6/site-packages/pandas/core/frame.py", line 2927, in __getitem__
    indexer = self.columns.get_loc(key)
  File "/home/shinto/Documents/virtual_envs/rate_api/lib/python3.6/site-packages/pandas/core/indexes/base.py", line 2659, in get_loc
    return self._engine.get_loc(self._maybe_cast_indexer(key))
  File "pandas/_libs/index.pyx", line 108, in pandas._libs.index.IndexEngine.get_loc
  File "pandas/_libs/index.pyx", line 132, in pandas._libs.index.IndexEngine.get_loc
  File "pandas/_libs/hashtable_class_helper.pxi", line 1601, in pandas._libs.hashtable.PyObjectHashTable.get_item
  File "pandas/_libs/hashtable_class_helper.pxi", line 1608, in pandas._libs.hashtable.PyObjectHashTable.get_item
KeyError: 'day'
ERROR "GET /api/rates_null/2016-01-01/2016-01-10/CNSGH/north_europe_main/ HTTP/1.1" 500 19637
ERROR Internal Server Error: /api/rates/2016-01-01/2016-01-01/CNSGH/north_europe_main/
Traceback (most recent call last):
  File "/home/shinto/Documents/virtual_envs/rate_api/lib/python3.6/site-packages/pandas/core/indexes/base.py", line 2657, in get_loc
    return self._engine.get_loc(key)
  File "pandas/_libs/index.pyx", line 108, in pandas._libs.index.IndexEngine.get_loc
  File "pandas/_libs/index.pyx", line 132, in pandas._libs.index.IndexEngine.get_loc
  File "pandas/_libs/hashtable_class_helper.pxi", line 1601, in pandas._libs.hashtable.PyObjectHashTable.get_item
  File "pandas/_libs/hashtable_class_helper.pxi", line 1608, in pandas._libs.hashtable.PyObjectHashTable.get_item
KeyError: 'day'

During handling of the above exception, another exception occurred:

Traceback (most recent call last):
  File "/home/shinto/Documents/virtual_envs/rate_api/lib/python3.6/site-packages/django/core/handlers/exception.py", line 34, in inner
    response = get_response(request)
  File "/home/shinto/Documents/virtual_envs/rate_api/lib/python3.6/site-packages/django/core/handlers/base.py", line 115, in _get_response
    response = self.process_exception_by_middleware(e, request)
  File "/home/shinto/Documents/virtual_envs/rate_api/lib/python3.6/site-packages/django/core/handlers/base.py", line 113, in _get_response
    response = wrapped_callback(request, *callback_args, **callback_kwargs)
  File "/home/shinto/Documents/virtual_envs/rate_api/lib/python3.6/site-packages/django/views/decorators/csrf.py", line 54, in wrapped_view
    return view_func(*args, **kwargs)
  File "/home/shinto/Documents/virtual_envs/rate_api/lib/python3.6/site-packages/django/views/generic/base.py", line 71, in view
    return self.dispatch(request, *args, **kwargs)
  File "/home/shinto/Documents/virtual_envs/rate_api/lib/python3.6/site-packages/rest_framework/views.py", line 495, in dispatch
    response = self.handle_exception(exc)
  File "/home/shinto/Documents/virtual_envs/rate_api/lib/python3.6/site-packages/rest_framework/views.py", line 455, in handle_exception
    self.raise_uncaught_exception(exc)
  File "/home/shinto/Documents/virtual_envs/rate_api/lib/python3.6/site-packages/rest_framework/views.py", line 492, in dispatch
    response = handler(request, *args, **kwargs)
  File "/home/shinto/Documents/virtual_envs/rate_api/lib/python3.6/site-packages/rest_framework/decorators.py", line 55, in handler
    return func(*args, **kwargs)
  File "/home/shinto/Documents/projects/rate_project/rate_api/rate_api/api/views.py", line 164, in rates
    mean_df = df.groupby(df['day']).mean().astype(int)
  File "/home/shinto/Documents/virtual_envs/rate_api/lib/python3.6/site-packages/pandas/core/frame.py", line 2927, in __getitem__
    indexer = self.columns.get_loc(key)
  File "/home/shinto/Documents/virtual_envs/rate_api/lib/python3.6/site-packages/pandas/core/indexes/base.py", line 2659, in get_loc
    return self._engine.get_loc(self._maybe_cast_indexer(key))
  File "pandas/_libs/index.pyx", line 108, in pandas._libs.index.IndexEngine.get_loc
  File "pandas/_libs/index.pyx", line 132, in pandas._libs.index.IndexEngine.get_loc
  File "pandas/_libs/hashtable_class_helper.pxi", line 1601, in pandas._libs.hashtable.PyObjectHashTable.get_item
  File "pandas/_libs/hashtable_class_helper.pxi", line 1608, in pandas._libs.hashtable.PyObjectHashTable.get_item
KeyError: 'day'
ERROR "GET /api/rates/2016-01-01/2016-01-01/CNSGH/north_europe_main/ HTTP/1.1" 500 19414
ERROR Internal Server Error: /api/rates/2016-01-01/2016-01-01/CNSGH/north_europe_main/
Traceback (most recent call last):
  File "/home/shinto/Documents/virtual_envs/rate_api/lib/python3.6/site-packages/pandas/core/indexes/base.py", line 2657, in get_loc
    return self._engine.get_loc(key)
  File "pandas/_libs/index.pyx", line 108, in pandas._libs.index.IndexEngine.get_loc
  File "pandas/_libs/index.pyx", line 132, in pandas._libs.index.IndexEngine.get_loc
  File "pandas/_libs/hashtable_class_helper.pxi", line 1601, in pandas._libs.hashtable.PyObjectHashTable.get_item
  File "pandas/_libs/hashtable_class_helper.pxi", line 1608, in pandas._libs.hashtable.PyObjectHashTable.get_item
KeyError: 'day'

During handling of the above exception, another exception occurred:

Traceback (most recent call last):
  File "/home/shinto/Documents/virtual_envs/rate_api/lib/python3.6/site-packages/django/core/handlers/exception.py", line 34, in inner
    response = get_response(request)
  File "/home/shinto/Documents/virtual_envs/rate_api/lib/python3.6/site-packages/django/core/handlers/base.py", line 115, in _get_response
    response = self.process_exception_by_middleware(e, request)
  File "/home/shinto/Documents/virtual_envs/rate_api/lib/python3.6/site-packages/django/core/handlers/base.py", line 113, in _get_response
    response = wrapped_callback(request, *callback_args, **callback_kwargs)
  File "/home/shinto/Documents/virtual_envs/rate_api/lib/python3.6/site-packages/django/views/decorators/csrf.py", line 54, in wrapped_view
    return view_func(*args, **kwargs)
  File "/home/shinto/Documents/virtual_envs/rate_api/lib/python3.6/site-packages/django/views/generic/base.py", line 71, in view
    return self.dispatch(request, *args, **kwargs)
  File "/home/shinto/Documents/virtual_envs/rate_api/lib/python3.6/site-packages/rest_framework/views.py", line 495, in dispatch
    response = self.handle_exception(exc)
  File "/home/shinto/Documents/virtual_envs/rate_api/lib/python3.6/site-packages/rest_framework/views.py", line 455, in handle_exception
    self.raise_uncaught_exception(exc)
  File "/home/shinto/Documents/virtual_envs/rate_api/lib/python3.6/site-packages/rest_framework/views.py", line 492, in dispatch
    response = handler(request, *args, **kwargs)
  File "/home/shinto/Documents/virtual_envs/rate_api/lib/python3.6/site-packages/rest_framework/decorators.py", line 55, in handler
    return func(*args, **kwargs)
  File "/home/shinto/Documents/projects/rate_project/rate_api/rate_api/api/views.py", line 164, in rates
    mean_df = df.groupby(df['day']).mean().astype(int)
  File "/home/shinto/Documents/virtual_envs/rate_api/lib/python3.6/site-packages/pandas/core/frame.py", line 2927, in __getitem__
    indexer = self.columns.get_loc(key)
  File "/home/shinto/Documents/virtual_envs/rate_api/lib/python3.6/site-packages/pandas/core/indexes/base.py", line 2659, in get_loc
    return self._engine.get_loc(self._maybe_cast_indexer(key))
  File "pandas/_libs/index.pyx", line 108, in pandas._libs.index.IndexEngine.get_loc
  File "pandas/_libs/index.pyx", line 132, in pandas._libs.index.IndexEngine.get_loc
  File "pandas/_libs/hashtable_class_helper.pxi", line 1601, in pandas._libs.hashtable.PyObjectHashTable.get_item
  File "pandas/_libs/hashtable_class_helper.pxi", line 1608, in pandas._libs.hashtable.PyObjectHashTable.get_item
KeyError: 'day'
ERROR "GET /api/rates/2016-01-01/2016-01-01/CNSGH/north_europe_main/ HTTP/1.1" 500 19414
ERROR Internal Server Error: /api/rates/2016-01-01/2016-01-01/CNSGH/north_europe_main/
Traceback (most recent call last):
  File "/home/shinto/Documents/virtual_envs/rate_api/lib/python3.6/site-packages/pandas/core/indexes/base.py", line 2657, in get_loc
    return self._engine.get_loc(key)
  File "pandas/_libs/index.pyx", line 108, in pandas._libs.index.IndexEngine.get_loc
  File "pandas/_libs/index.pyx", line 132, in pandas._libs.index.IndexEngine.get_loc
  File "pandas/_libs/hashtable_class_helper.pxi", line 1601, in pandas._libs.hashtable.PyObjectHashTable.get_item
  File "pandas/_libs/hashtable_class_helper.pxi", line 1608, in pandas._libs.hashtable.PyObjectHashTable.get_item
KeyError: 'day'

During handling of the above exception, another exception occurred:

Traceback (most recent call last):
  File "/home/shinto/Documents/virtual_envs/rate_api/lib/python3.6/site-packages/django/core/handlers/exception.py", line 34, in inner
    response = get_response(request)
  File "/home/shinto/Documents/virtual_envs/rate_api/lib/python3.6/site-packages/django/core/handlers/base.py", line 115, in _get_response
    response = self.process_exception_by_middleware(e, request)
  File "/home/shinto/Documents/virtual_envs/rate_api/lib/python3.6/site-packages/django/core/handlers/base.py", line 113, in _get_response
    response = wrapped_callback(request, *callback_args, **callback_kwargs)
  File "/home/shinto/Documents/virtual_envs/rate_api/lib/python3.6/site-packages/django/views/decorators/csrf.py", line 54, in wrapped_view
    return view_func(*args, **kwargs)
  File "/home/shinto/Documents/virtual_envs/rate_api/lib/python3.6/site-packages/django/views/generic/base.py", line 71, in view
    return self.dispatch(request, *args, **kwargs)
  File "/home/shinto/Documents/virtual_envs/rate_api/lib/python3.6/site-packages/rest_framework/views.py", line 495, in dispatch
    response = self.handle_exception(exc)
  File "/home/shinto/Documents/virtual_envs/rate_api/lib/python3.6/site-packages/rest_framework/views.py", line 455, in handle_exception
    self.raise_uncaught_exception(exc)
  File "/home/shinto/Documents/virtual_envs/rate_api/lib/python3.6/site-packages/rest_framework/views.py", line 492, in dispatch
    response = handler(request, *args, **kwargs)
  File "/home/shinto/Documents/virtual_envs/rate_api/lib/python3.6/site-packages/rest_framework/decorators.py", line 55, in handler
    return func(*args, **kwargs)
  File "/home/shinto/Documents/projects/rate_project/rate_api/rate_api/api/views.py", line 162, in rates
    mean_df = df.groupby(df['day']).mean().astype(int)
  File "/home/shinto/Documents/virtual_envs/rate_api/lib/python3.6/site-packages/pandas/core/frame.py", line 2927, in __getitem__
    indexer = self.columns.get_loc(key)
  File "/home/shinto/Documents/virtual_envs/rate_api/lib/python3.6/site-packages/pandas/core/indexes/base.py", line 2659, in get_loc
    return self._engine.get_loc(self._maybe_cast_indexer(key))
  File "pandas/_libs/index.pyx", line 108, in pandas._libs.index.IndexEngine.get_loc
  File "pandas/_libs/index.pyx", line 132, in pandas._libs.index.IndexEngine.get_loc
  File "pandas/_libs/hashtable_class_helper.pxi", line 1601, in pandas._libs.hashtable.PyObjectHashTable.get_item
  File "pandas/_libs/hashtable_class_helper.pxi", line 1608, in pandas._libs.hashtable.PyObjectHashTable.get_item
KeyError: 'day'
ERROR "GET /api/rates/2016-01-01/2016-01-01/CNSGH/north_europe_main/ HTTP/1.1" 500 19414
ERROR Internal Server Error: /api/rates/2016-01-01/2016-01-01/CNSGH/north_europe_main/
Traceback (most recent call last):
  File "/home/shinto/Documents/virtual_envs/rate_api/lib/python3.6/site-packages/pandas/core/indexes/base.py", line 2657, in get_loc
    return self._engine.get_loc(key)
  File "pandas/_libs/index.pyx", line 108, in pandas._libs.index.IndexEngine.get_loc
  File "pandas/_libs/index.pyx", line 132, in pandas._libs.index.IndexEngine.get_loc
  File "pandas/_libs/hashtable_class_helper.pxi", line 1601, in pandas._libs.hashtable.PyObjectHashTable.get_item
  File "pandas/_libs/hashtable_class_helper.pxi", line 1608, in pandas._libs.hashtable.PyObjectHashTable.get_item
KeyError: 'day'

During handling of the above exception, another exception occurred:

Traceback (most recent call last):
  File "/home/shinto/Documents/virtual_envs/rate_api/lib/python3.6/site-packages/django/core/handlers/exception.py", line 34, in inner
    response = get_response(request)
  File "/home/shinto/Documents/virtual_envs/rate_api/lib/python3.6/site-packages/django/core/handlers/base.py", line 115, in _get_response
    response = self.process_exception_by_middleware(e, request)
  File "/home/shinto/Documents/virtual_envs/rate_api/lib/python3.6/site-packages/django/core/handlers/base.py", line 113, in _get_response
    response = wrapped_callback(request, *callback_args, **callback_kwargs)
  File "/home/shinto/Documents/virtual_envs/rate_api/lib/python3.6/site-packages/django/views/decorators/csrf.py", line 54, in wrapped_view
    return view_func(*args, **kwargs)
  File "/home/shinto/Documents/virtual_envs/rate_api/lib/python3.6/site-packages/django/views/generic/base.py", line 71, in view
    return self.dispatch(request, *args, **kwargs)
  File "/home/shinto/Documents/virtual_envs/rate_api/lib/python3.6/site-packages/rest_framework/views.py", line 495, in dispatch
    response = self.handle_exception(exc)
  File "/home/shinto/Documents/virtual_envs/rate_api/lib/python3.6/site-packages/rest_framework/views.py", line 455, in handle_exception
    self.raise_uncaught_exception(exc)
  File "/home/shinto/Documents/virtual_envs/rate_api/lib/python3.6/site-packages/rest_framework/views.py", line 492, in dispatch
    response = handler(request, *args, **kwargs)
  File "/home/shinto/Documents/virtual_envs/rate_api/lib/python3.6/site-packages/rest_framework/decorators.py", line 55, in handler
    return func(*args, **kwargs)
  File "/home/shinto/Documents/projects/rate_project/rate_api/rate_api/api/views.py", line 160, in rates
    mean_df = df.groupby(df['day']).mean().astype(int)
  File "/home/shinto/Documents/virtual_envs/rate_api/lib/python3.6/site-packages/pandas/core/frame.py", line 2927, in __getitem__
    indexer = self.columns.get_loc(key)
  File "/home/shinto/Documents/virtual_envs/rate_api/lib/python3.6/site-packages/pandas/core/indexes/base.py", line 2659, in get_loc
    return self._engine.get_loc(self._maybe_cast_indexer(key))
  File "pandas/_libs/index.pyx", line 108, in pandas._libs.index.IndexEngine.get_loc
  File "pandas/_libs/index.pyx", line 132, in pandas._libs.index.IndexEngine.get_loc
  File "pandas/_libs/hashtable_class_helper.pxi", line 1601, in pandas._libs.hashtable.PyObjectHashTable.get_item
  File "pandas/_libs/hashtable_class_helper.pxi", line 1608, in pandas._libs.hashtable.PyObjectHashTable.get_item
KeyError: 'day'
ERROR "GET /api/rates/2016-01-01/2016-01-01/CNSGH/north_europe_main/ HTTP/1.1" 500 19418
ERROR Internal Server Error: /api/upload/
Traceback (most recent call last):
  File "/home/shinto/Documents/virtual_envs/rate_api/lib/python3.6/site-packages/django/db/models/query.py", line 538, in get_or_create
    return self.get(**kwargs), False
  File "/home/shinto/Documents/virtual_envs/rate_api/lib/python3.6/site-packages/django/db/models/query.py", line 408, in get
    self.model._meta.object_name
api.models.Prices.DoesNotExist: Prices matching query does not exist.

During handling of the above exception, another exception occurred:

Traceback (most recent call last):
  File "/home/shinto/Documents/virtual_envs/rate_api/lib/python3.6/site-packages/django/db/backends/utils.py", line 84, in _execute
    return self.cursor.execute(sql, params)
  File "/home/shinto/Documents/virtual_envs/rate_api/lib/python3.6/site-packages/django/db/backends/sqlite3/base.py", line 383, in execute
    return Database.Cursor.execute(self, query, params)
sqlite3.IntegrityError: NOT NULL constraint failed: api_prices.price

The above exception was the direct cause of the following exception:

Traceback (most recent call last):
  File "/home/shinto/Documents/virtual_envs/rate_api/lib/python3.6/site-packages/django/core/handlers/exception.py", line 34, in inner
    response = get_response(request)
  File "/home/shinto/Documents/virtual_envs/rate_api/lib/python3.6/site-packages/django/core/handlers/base.py", line 115, in _get_response
    response = self.process_exception_by_middleware(e, request)
  File "/home/shinto/Documents/virtual_envs/rate_api/lib/python3.6/site-packages/django/core/handlers/base.py", line 113, in _get_response
    response = wrapped_callback(request, *callback_args, **callback_kwargs)
  File "/home/shinto/Documents/virtual_envs/rate_api/lib/python3.6/site-packages/django/views/decorators/csrf.py", line 54, in wrapped_view
    return view_func(*args, **kwargs)
  File "/home/shinto/Documents/virtual_envs/rate_api/lib/python3.6/site-packages/django/views/generic/base.py", line 71, in view
    return self.dispatch(request, *args, **kwargs)
  File "/home/shinto/Documents/virtual_envs/rate_api/lib/python3.6/site-packages/rest_framework/views.py", line 495, in dispatch
    response = self.handle_exception(exc)
  File "/home/shinto/Documents/virtual_envs/rate_api/lib/python3.6/site-packages/rest_framework/views.py", line 455, in handle_exception
    self.raise_uncaught_exception(exc)
  File "/home/shinto/Documents/virtual_envs/rate_api/lib/python3.6/site-packages/rest_framework/views.py", line 492, in dispatch
    response = handler(request, *args, **kwargs)
  File "/home/shinto/Documents/projects/rate_project/rate_api/rate_api/api/views.py", line 270, in post
    day         = date,
  File "/home/shinto/Documents/virtual_envs/rate_api/lib/python3.6/site-packages/django/db/models/manager.py", line 82, in manager_method
    return getattr(self.get_queryset(), name)(*args, **kwargs)
  File "/home/shinto/Documents/virtual_envs/rate_api/lib/python3.6/site-packages/django/db/models/query.py", line 541, in get_or_create
    return self._create_object_from_params(kwargs, params)
  File "/home/shinto/Documents/virtual_envs/rate_api/lib/python3.6/site-packages/django/db/models/query.py", line 583, in _create_object_from_params
    raise e
  File "/home/shinto/Documents/virtual_envs/rate_api/lib/python3.6/site-packages/django/db/models/query.py", line 575, in _create_object_from_params
    obj = self.create(**params)
  File "/home/shinto/Documents/virtual_envs/rate_api/lib/python3.6/site-packages/django/db/models/query.py", line 422, in create
    obj.save(force_insert=True, using=self.db)
  File "/home/shinto/Documents/virtual_envs/rate_api/lib/python3.6/site-packages/django/db/models/base.py", line 741, in save
    force_update=force_update, update_fields=update_fields)
  File "/home/shinto/Documents/virtual_envs/rate_api/lib/python3.6/site-packages/django/db/models/base.py", line 779, in save_base
    force_update, using, update_fields,
  File "/home/shinto/Documents/virtual_envs/rate_api/lib/python3.6/site-packages/django/db/models/base.py", line 870, in _save_table
    result = self._do_insert(cls._base_manager, using, fields, update_pk, raw)
  File "/home/shinto/Documents/virtual_envs/rate_api/lib/python3.6/site-packages/django/db/models/base.py", line 908, in _do_insert
    using=using, raw=raw)
  File "/home/shinto/Documents/virtual_envs/rate_api/lib/python3.6/site-packages/django/db/models/manager.py", line 82, in manager_method
    return getattr(self.get_queryset(), name)(*args, **kwargs)
  File "/home/shinto/Documents/virtual_envs/rate_api/lib/python3.6/site-packages/django/db/models/query.py", line 1186, in _insert
    return query.get_compiler(using=using).execute_sql(return_id)
  File "/home/shinto/Documents/virtual_envs/rate_api/lib/python3.6/site-packages/django/db/models/sql/compiler.py", line 1335, in execute_sql
    cursor.execute(sql, params)
  File "/home/shinto/Documents/virtual_envs/rate_api/lib/python3.6/site-packages/django/db/backends/utils.py", line 99, in execute
    return super().execute(sql, params)
  File "/home/shinto/Documents/virtual_envs/rate_api/lib/python3.6/site-packages/django/db/backends/utils.py", line 67, in execute
    return self._execute_with_wrappers(sql, params, many=False, executor=self._execute)
  File "/home/shinto/Documents/virtual_envs/rate_api/lib/python3.6/site-packages/django/db/backends/utils.py", line 76, in _execute_with_wrappers
    return executor(sql, params, many, context)
  File "/home/shinto/Documents/virtual_envs/rate_api/lib/python3.6/site-packages/django/db/backends/utils.py", line 84, in _execute
    return self.cursor.execute(sql, params)
  File "/home/shinto/Documents/virtual_envs/rate_api/lib/python3.6/site-packages/django/db/utils.py", line 89, in __exit__
    raise dj_exc_value.with_traceback(traceback) from exc_value
  File "/home/shinto/Documents/virtual_envs/rate_api/lib/python3.6/site-packages/django/db/backends/utils.py", line 84, in _execute
    return self.cursor.execute(sql, params)
  File "/home/shinto/Documents/virtual_envs/rate_api/lib/python3.6/site-packages/django/db/backends/sqlite3/base.py", line 383, in execute
    return Database.Cursor.execute(self, query, params)
django.db.utils.IntegrityError: NOT NULL constraint failed: api_prices.price
ERROR "POST /api/upload/ HTTP/1.1" 500 22136
ERROR Internal Server Error: /api/upload/
Traceback (most recent call last):
  File "/home/shinto/Documents/virtual_envs/rate_api/lib/python3.6/site-packages/django/core/handlers/exception.py", line 34, in inner
    response = get_response(request)
  File "/home/shinto/Documents/virtual_envs/rate_api/lib/python3.6/site-packages/django/core/handlers/base.py", line 115, in _get_response
    response = self.process_exception_by_middleware(e, request)
  File "/home/shinto/Documents/virtual_envs/rate_api/lib/python3.6/site-packages/django/core/handlers/base.py", line 113, in _get_response
    response = wrapped_callback(request, *callback_args, **callback_kwargs)
  File "/home/shinto/Documents/virtual_envs/rate_api/lib/python3.6/site-packages/django/views/decorators/csrf.py", line 54, in wrapped_view
    return view_func(*args, **kwargs)
  File "/home/shinto/Documents/virtual_envs/rate_api/lib/python3.6/site-packages/django/views/generic/base.py", line 71, in view
    return self.dispatch(request, *args, **kwargs)
  File "/home/shinto/Documents/virtual_envs/rate_api/lib/python3.6/site-packages/rest_framework/views.py", line 495, in dispatch
    response = self.handle_exception(exc)
  File "/home/shinto/Documents/virtual_envs/rate_api/lib/python3.6/site-packages/rest_framework/views.py", line 455, in handle_exception
    self.raise_uncaught_exception(exc)
  File "/home/shinto/Documents/virtual_envs/rate_api/lib/python3.6/site-packages/rest_framework/views.py", line 492, in dispatch
    response = handler(request, *args, **kwargs)
  File "/home/shinto/Documents/projects/rate_project/rate_api/rate_api/api/views.py", line 274, in post
    prices.save(price=price)
AttributeError: 'tuple' object has no attribute 'save'
ERROR "POST /api/upload/ HTTP/1.1" 500 17520
ERROR Internal Server Error: /api/upload/
Traceback (most recent call last):
  File "/home/shinto/Documents/virtual_envs/rate_api/lib/python3.6/site-packages/django/core/handlers/exception.py", line 34, in inner
    response = get_response(request)
  File "/home/shinto/Documents/virtual_envs/rate_api/lib/python3.6/site-packages/django/core/handlers/base.py", line 115, in _get_response
    response = self.process_exception_by_middleware(e, request)
  File "/home/shinto/Documents/virtual_envs/rate_api/lib/python3.6/site-packages/django/core/handlers/base.py", line 113, in _get_response
    response = wrapped_callback(request, *callback_args, **callback_kwargs)
  File "/home/shinto/Documents/virtual_envs/rate_api/lib/python3.6/site-packages/django/views/decorators/csrf.py", line 54, in wrapped_view
    return view_func(*args, **kwargs)
  File "/home/shinto/Documents/virtual_envs/rate_api/lib/python3.6/site-packages/django/views/generic/base.py", line 71, in view
    return self.dispatch(request, *args, **kwargs)
  File "/home/shinto/Documents/virtual_envs/rate_api/lib/python3.6/site-packages/rest_framework/views.py", line 495, in dispatch
    response = self.handle_exception(exc)
  File "/home/shinto/Documents/virtual_envs/rate_api/lib/python3.6/site-packages/rest_framework/views.py", line 455, in handle_exception
    self.raise_uncaught_exception(exc)
  File "/home/shinto/Documents/virtual_envs/rate_api/lib/python3.6/site-packages/rest_framework/views.py", line 492, in dispatch
    response = handler(request, *args, **kwargs)
  File "/home/shinto/Documents/projects/rate_project/rate_api/rate_api/api/views.py", line 274, in post
    prices.save(price=price)
AttributeError: 'tuple' object has no attribute 'save'
ERROR "POST /api/upload/ HTTP/1.1" 500 17520
ERROR Internal Server Error: /api/upload/
Traceback (most recent call last):
  File "/home/shinto/Documents/virtual_envs/rate_api/lib/python3.6/site-packages/django/core/handlers/exception.py", line 34, in inner
    response = get_response(request)
  File "/home/shinto/Documents/virtual_envs/rate_api/lib/python3.6/site-packages/django/core/handlers/base.py", line 115, in _get_response
    response = self.process_exception_by_middleware(e, request)
  File "/home/shinto/Documents/virtual_envs/rate_api/lib/python3.6/site-packages/django/core/handlers/base.py", line 113, in _get_response
    response = wrapped_callback(request, *callback_args, **callback_kwargs)
  File "/home/shinto/Documents/virtual_envs/rate_api/lib/python3.6/site-packages/django/views/decorators/csrf.py", line 54, in wrapped_view
    return view_func(*args, **kwargs)
  File "/home/shinto/Documents/virtual_envs/rate_api/lib/python3.6/site-packages/django/views/generic/base.py", line 71, in view
    return self.dispatch(request, *args, **kwargs)
  File "/home/shinto/Documents/virtual_envs/rate_api/lib/python3.6/site-packages/rest_framework/views.py", line 495, in dispatch
    response = self.handle_exception(exc)
  File "/home/shinto/Documents/virtual_envs/rate_api/lib/python3.6/site-packages/rest_framework/views.py", line 455, in handle_exception
    self.raise_uncaught_exception(exc)
  File "/home/shinto/Documents/virtual_envs/rate_api/lib/python3.6/site-packages/rest_framework/views.py", line 492, in dispatch
    response = handler(request, *args, **kwargs)
  File "/home/shinto/Documents/projects/rate_project/rate_api/rate_api/api/views.py", line 276, in post
    print (prices)
NameError: name 'prices' is not defined
ERROR "POST /api/upload/ HTTP/1.1" 500 17480
ERROR Internal Server Error: /api/upload/
Traceback (most recent call last):
  File "/home/shinto/Documents/virtual_envs/rate_api/lib/python3.6/site-packages/django/core/handlers/exception.py", line 34, in inner
    response = get_response(request)
  File "/home/shinto/Documents/virtual_envs/rate_api/lib/python3.6/site-packages/django/core/handlers/base.py", line 115, in _get_response
    response = self.process_exception_by_middleware(e, request)
  File "/home/shinto/Documents/virtual_envs/rate_api/lib/python3.6/site-packages/django/core/handlers/base.py", line 113, in _get_response
    response = wrapped_callback(request, *callback_args, **callback_kwargs)
  File "/home/shinto/Documents/virtual_envs/rate_api/lib/python3.6/site-packages/django/views/decorators/csrf.py", line 54, in wrapped_view
    return view_func(*args, **kwargs)
  File "/home/shinto/Documents/virtual_envs/rate_api/lib/python3.6/site-packages/django/views/generic/base.py", line 71, in view
    return self.dispatch(request, *args, **kwargs)
  File "/home/shinto/Documents/virtual_envs/rate_api/lib/python3.6/site-packages/rest_framework/views.py", line 495, in dispatch
    response = self.handle_exception(exc)
  File "/home/shinto/Documents/virtual_envs/rate_api/lib/python3.6/site-packages/rest_framework/views.py", line 455, in handle_exception
    self.raise_uncaught_exception(exc)
  File "/home/shinto/Documents/virtual_envs/rate_api/lib/python3.6/site-packages/rest_framework/views.py", line 492, in dispatch
    response = handler(request, *args, **kwargs)
  File "/home/shinto/Documents/projects/rate_project/rate_api/rate_api/api/views.py", line 276, in post
    print (prices)
NameError: name 'prices' is not defined
ERROR "POST /api/upload/ HTTP/1.1" 500 17480
ERROR Internal Server Error: /api/rates/2016-01-01/2016-01-02/CNGGZ/EETLL/
Traceback (most recent call last):
  File "/home/shinto/Documents/virtual_envs/rate_api/lib/python3.6/site-packages/django/core/handlers/exception.py", line 34, in inner
    response = get_response(request)
  File "/home/shinto/Documents/virtual_envs/rate_api/lib/python3.6/site-packages/django/core/handlers/base.py", line 115, in _get_response
    response = self.process_exception_by_middleware(e, request)
  File "/home/shinto/Documents/virtual_envs/rate_api/lib/python3.6/site-packages/django/core/handlers/base.py", line 113, in _get_response
    response = wrapped_callback(request, *callback_args, **callback_kwargs)
  File "/home/shinto/Documents/virtual_envs/rate_api/lib/python3.6/site-packages/django/views/decorators/csrf.py", line 54, in wrapped_view
    return view_func(*args, **kwargs)
  File "/home/shinto/Documents/virtual_envs/rate_api/lib/python3.6/site-packages/django/views/generic/base.py", line 71, in view
    return self.dispatch(request, *args, **kwargs)
  File "/home/shinto/Documents/virtual_envs/rate_api/lib/python3.6/site-packages/rest_framework/views.py", line 495, in dispatch
    response = self.handle_exception(exc)
  File "/home/shinto/Documents/virtual_envs/rate_api/lib/python3.6/site-packages/rest_framework/views.py", line 455, in handle_exception
    self.raise_uncaught_exception(exc)
  File "/home/shinto/Documents/virtual_envs/rate_api/lib/python3.6/site-packages/rest_framework/views.py", line 492, in dispatch
    response = handler(request, *args, **kwargs)
  File "/home/shinto/Documents/virtual_envs/rate_api/lib/python3.6/site-packages/rest_framework/decorators.py", line 55, in handler
    return func(*args, **kwargs)
  File "/home/shinto/Documents/projects/rate_project/rate_api/rate_api/api/views.py", line 139, in rates
    Price.objects.all().delete()
NameError: name 'Price' is not defined
ERROR "GET /api/rates/2016-01-01/2016-01-02/CNGGZ/EETLL/ HTTP/1.1" 500 17780
ERROR Internal Server Error: /
Traceback (most recent call last):
  File "/home/shinto/Documents/virtual_envs/rate_api/lib/python3.6/site-packages/django/template/base.py", line 470, in parse
    compile_func = self.tags[command]
KeyError: 'static'

During handling of the above exception, another exception occurred:

Traceback (most recent call last):
  File "/home/shinto/Documents/virtual_envs/rate_api/lib/python3.6/site-packages/django/core/handlers/exception.py", line 34, in inner
    response = get_response(request)
  File "/home/shinto/Documents/virtual_envs/rate_api/lib/python3.6/site-packages/django/core/handlers/base.py", line 115, in _get_response
    response = self.process_exception_by_middleware(e, request)
  File "/home/shinto/Documents/virtual_envs/rate_api/lib/python3.6/site-packages/django/core/handlers/base.py", line 113, in _get_response
    response = wrapped_callback(request, *callback_args, **callback_kwargs)
  File "/home/shinto/Documents/projects/rate_project/rate_api/rate_api/rate_api/views.py", line 7, in index
    return render(request, "index.html", {})
  File "/home/shinto/Documents/virtual_envs/rate_api/lib/python3.6/site-packages/django/shortcuts.py", line 36, in render
    content = loader.render_to_string(template_name, context, request, using=using)
  File "/home/shinto/Documents/virtual_envs/rate_api/lib/python3.6/site-packages/django/template/loader.py", line 61, in render_to_string
    template = get_template(template_name, using=using)
  File "/home/shinto/Documents/virtual_envs/rate_api/lib/python3.6/site-packages/django/template/loader.py", line 15, in get_template
    return engine.get_template(template_name)
  File "/home/shinto/Documents/virtual_envs/rate_api/lib/python3.6/site-packages/django/template/backends/django.py", line 34, in get_template
    return Template(self.engine.get_template(template_name), self)
  File "/home/shinto/Documents/virtual_envs/rate_api/lib/python3.6/site-packages/django/template/engine.py", line 143, in get_template
    template, origin = self.find_template(template_name)
  File "/home/shinto/Documents/virtual_envs/rate_api/lib/python3.6/site-packages/django/template/engine.py", line 125, in find_template
    template = loader.get_template(name, skip=skip)
  File "/home/shinto/Documents/virtual_envs/rate_api/lib/python3.6/site-packages/django/template/loaders/base.py", line 30, in get_template
    contents, origin, origin.template_name, self.engine,
  File "/home/shinto/Documents/virtual_envs/rate_api/lib/python3.6/site-packages/django/template/base.py", line 156, in __init__
    self.nodelist = self.compile_nodelist()
  File "/home/shinto/Documents/virtual_envs/rate_api/lib/python3.6/site-packages/django/template/base.py", line 194, in compile_nodelist
    return parser.parse()
  File "/home/shinto/Documents/virtual_envs/rate_api/lib/python3.6/site-packages/django/template/base.py", line 472, in parse
    self.invalid_block_tag(token, command, parse_until)
  File "/home/shinto/Documents/virtual_envs/rate_api/lib/python3.6/site-packages/django/template/base.py", line 534, in invalid_block_tag
    "or load this tag?" % (token.lineno, command)
django.template.exceptions.TemplateSyntaxError: Invalid block tag on line 15: 'static'. Did you forget to register or load this tag?
ERROR "GET / HTTP/1.1" 500 141177
ERROR Internal Server Error: /
Traceback (most recent call last):
  File "/home/shinto/Documents/virtual_envs/rate_api/lib/python3.6/site-packages/django/template/base.py", line 470, in parse
    compile_func = self.tags[command]
KeyError: 'static'

During handling of the above exception, another exception occurred:

Traceback (most recent call last):
  File "/home/shinto/Documents/virtual_envs/rate_api/lib/python3.6/site-packages/django/core/handlers/exception.py", line 34, in inner
    response = get_response(request)
  File "/home/shinto/Documents/virtual_envs/rate_api/lib/python3.6/site-packages/django/core/handlers/base.py", line 115, in _get_response
    response = self.process_exception_by_middleware(e, request)
  File "/home/shinto/Documents/virtual_envs/rate_api/lib/python3.6/site-packages/django/core/handlers/base.py", line 113, in _get_response
    response = wrapped_callback(request, *callback_args, **callback_kwargs)
  File "/home/shinto/Documents/projects/rate_project/rate_api/rate_api/rate_api/views.py", line 7, in index
    return render(request, "index.html", {})
  File "/home/shinto/Documents/virtual_envs/rate_api/lib/python3.6/site-packages/django/shortcuts.py", line 36, in render
    content = loader.render_to_string(template_name, context, request, using=using)
  File "/home/shinto/Documents/virtual_envs/rate_api/lib/python3.6/site-packages/django/template/loader.py", line 61, in render_to_string
    template = get_template(template_name, using=using)
  File "/home/shinto/Documents/virtual_envs/rate_api/lib/python3.6/site-packages/django/template/loader.py", line 15, in get_template
    return engine.get_template(template_name)
  File "/home/shinto/Documents/virtual_envs/rate_api/lib/python3.6/site-packages/django/template/backends/django.py", line 34, in get_template
    return Template(self.engine.get_template(template_name), self)
  File "/home/shinto/Documents/virtual_envs/rate_api/lib/python3.6/site-packages/django/template/engine.py", line 143, in get_template
    template, origin = self.find_template(template_name)
  File "/home/shinto/Documents/virtual_envs/rate_api/lib/python3.6/site-packages/django/template/engine.py", line 125, in find_template
    template = loader.get_template(name, skip=skip)
  File "/home/shinto/Documents/virtual_envs/rate_api/lib/python3.6/site-packages/django/template/loaders/base.py", line 30, in get_template
    contents, origin, origin.template_name, self.engine,
  File "/home/shinto/Documents/virtual_envs/rate_api/lib/python3.6/site-packages/django/template/base.py", line 156, in __init__
    self.nodelist = self.compile_nodelist()
  File "/home/shinto/Documents/virtual_envs/rate_api/lib/python3.6/site-packages/django/template/base.py", line 194, in compile_nodelist
    return parser.parse()
  File "/home/shinto/Documents/virtual_envs/rate_api/lib/python3.6/site-packages/django/template/base.py", line 472, in parse
    self.invalid_block_tag(token, command, parse_until)
  File "/home/shinto/Documents/virtual_envs/rate_api/lib/python3.6/site-packages/django/template/base.py", line 534, in invalid_block_tag
    "or load this tag?" % (token.lineno, command)
django.template.exceptions.TemplateSyntaxError: Invalid block tag on line 19: 'static'. Did you forget to register or load this tag?
ERROR "GET / HTTP/1.1" 500 141337
